Workbook

Sheet Company Profile
A1: ملف الشركة - Company Profile
A2: نموذج تدريبي على دورة القيد المحاسبي المزدوج - أرقام وهمية لأغراض التدريب فقط
A4: اسم الشركة | B4: شركة التدريب المحاسبي النموذجية
A5: العملة | B5: ريال سعودي (SAR)
A6: تاريخ بداية المحاكاة | B6: 2026-01-01
A7: تاريخ التقرير الحالي | B7: 2026-01-31
A8: رأس المال المدفوع | B8: 20000000
A9: نسبة ضريبة الدخل التدريبية | B9: 0.15
A11: تعليمات التسجيل والمتابعة
A12: 1. سجّل كل عملية مالية كقيد مزدوج في ورقة (Journal) بحيث يتساوى إجمالي المدين مع إجمالي الدائن لكل قيد.
A13: 2. استخدم أرقام الحسابات المعتمدة في ورقة (COA) فقط عند التسجيل، ولا تُنشئ أرقام حسابات جديدة دون تحديثها هناك أولاً.
A14: 3. تابع رصيد كل حساب أولاً بأول من ورقة (General Ledger) عبر اختيار رقم الحساب من القائمة المنسدلة.
A15: 4. تأكد من توازن ورقة (Trial Balance) قبل إعداد القوائم المالية (Income Statement / Balance Sheet).
A16: 5. راجع أعمار الذمم في (AR/AP) وسوّ حساب البنك في (Bank) بشكل دوري.
A17: 6. سجّل أي مقترح تسوية في (Adjustments) وحدّث حالته بعد ترحيله كقيد في اليومية.
A18: 7. حدّث ورقة (Training Progress) بعد إنجاز كل موضوع تدريبي، ودوّن أي حدث مهم في (Company Log).
A20: دليل الألوان: أزرق = خلية إدخال يعدّلها المستخدم | أسود = صيغة محسوبة تلقائياً | أصفر = افتراض/معلمة تدريبية رئيسية | رمادي = عمود مساعد للحسابات (لا يُعدّل)

Sheet COA
A1: دليل الحسابات - Chart of Accounts
A3: رقم الحساب | B3: اسم الحساب | C3: نوع الحساب | D3: طبيعة الرصيد | E3: ملاحظات
A4: 1100 | B4: البنك | C4: أصل | D4: مدين | E4: حساب بنكي رئيسي واحد للتدريب
A5: 1200 | B5: العملاء (المدينون) | C5: أصل | D5: مدين | E5: مرتبط بتفاصيل ورقة Customers
A6: 1300 | B6: المخزون | C6: أصل | D6: مدين
A7: 1400 | B7: معدات وأجهزة | C7: أصل | D7: مدين | E7: أصول ثابتة - انظر Fixed Assets
A8: 1450 | B8: مجمع إهلاك المعدات | C8: أصل مقابل (Contra) | D8: دائن | E8: يخصم من 1400
A9: 1500 | B9: مصروفات مدفوعة مقدماً | C9: أصل | D9: مدين
A10: 1600 | B10: ضريبة القيمة المضافة - مدخلات | C10: أصل | D10: مدين | E10: انظر ورقة VAT
A11: 2100 | B11: الموردون (الدائنون) | C11: التزام | D11: دائن | E11: مرتبط بتفاصيل ورقة Suppliers
A12: 2200 | B12: مصروفات مستحقة | C12: التزام | D12: دائن
A13: 2300 | B13: ضريبة القيمة المضافة - مخرجات | C13: التزام | D13: دائن | E13: انظر ورقة VAT
A14: 2400 | B14: ضريبة الدخل مستحقة | C14: التزام | D14: دائن
A15: 2500 | B15: قرض قصير الأجل | C15: التزام | D15: دائن
A16: 3100 | B16: رأس المال | C16: حقوق ملكية | D16: دائن | E16: رأس المال المدفوع
A17: 3200 | B17: الأرباح المحتجزة | C17: حقوق ملكية | D17: دائن | E17: ترحّل إليه الأرباح عند الإقفال
A18: 3300 | B18: مسحوبات / توزيعات أرباح | C18: حقوق ملكية | D18: مدين
A19: 4100 | B19: إيرادات المبيعات | C19: إيراد | D19: دائن
A20: 4200 | B20: إيرادات أخرى | C20: إيراد | D20: دائن
A21: 5100 | B21: تكلفة البضاعة المباعة | C21: مصروف | D21: مدين
A22: 5200 | B22: رواتب وأجور | C22: مصروف | D22: مدين
A23: 5300 | B23: إيجار | C23: مصروف | D23: مدين
A24: 5400 | B24: خدمات (كهرباء واتصالات) | C24: مصروف | D24: مدين
A25: 5500 | B25: مصروفات تسويق | C25: مصروف | D25: مدين
A26: 5600 | B26: مصروفات إدارية عامة | C26: مصروف | D26: مدين
A27: 5700 | B27: إهلاك | C27: مصروف | D27: مدين | E27: يقابله 1450
A28: 5800 | B28: مصروفات تمويل (فوائد بنكية) | C28: مصروف | D28: مدين
A30: دليل الألوان: أزرق = خلية إدخال يعدّلها المستخدم | أسود = صيغة محسوبة تلقائياً | أصفر = افتراض/معلمة تدريبية رئيسية | رمادي = عمود مساعد للحسابات (لا يُعدّل)

Sheet Opening Balances
A1: الأرصدة الافتتاحية - Opening Balances
A2: بداية المحاكاة: 1 يناير 2026
A4: رقم الحساب | B4: اسم الحساب | C4: مدين | D4: دائن
A5: 1100 | B5: =IFERROR(INDEX(COA!$B$4:$B$28,MATCH(A5,COA!$A$4:$A$28,0)),"") -> البنك | C5: 20000000 | D5: 0
A6: 3100 | B6: =IFERROR(INDEX(COA!$B$4:$B$28,MATCH(A6,COA!$A$4:$A$28,0)),"") -> رأس المال | C6: 0 | D6: 20000000
A7: الإجمالي | C7: =SUM(C5:C6) -> 20000000 | D7: =SUM(D5:D6) -> 20000000
A8: حالة التوازن | C8: =IF(C7=D7,"متوازن","غير متوازن") -> متوازن
A10: دليل الألوان: أزرق = خلية إدخال يعدّلها المستخدم | أسود = صيغة محسوبة تلقائياً | أصفر = افتراض/معلمة تدريبية رئيسية | رمادي = عمود مساعد للحسابات (لا يُعدّل)

Sheet Journal
A1: دفتر اليومية - General Journal
A2: سجّل كل قيد بحيث يتساوى مجموع المدين مع مجموع الدائن لنفس رقم القيد
A4: م | B4: رقم القيد | C4: التاريخ | D4: رقم الحساب | E4: اسم الحساب | F4: كود الطرف (عميل/مورد) - اختياري | G4: البيان | H4: مدين | I4: دائن | J4: حالة توازن القيد | K4: ترتيب الحساب (مساعد) | L4: مفتاح البحث (مساعد)
A5: 1 | E5: =IF(D5="","",IFERROR(INDEX(COA!$B$4:$B$28,MATCH(D5,COA!$A$4:$A$28,0)),"# غير موجود")) | J5: =IF(B5="","",IF(ROUND(SUMIF($B$5:$B$64,B5,$H$5:$H$64)-SUMIF($B$5:$B$64,B5,$I$5:$I$64),2)=0,"متوازن","غير متوازن")) | K5: =IF(D5="","",COUNTIFS($D$5:D5,D5)) | L5: =IF(D5="","",D5*1000+K5)
A6: 2 | E6: =IF(D6="","",IFERROR(INDEX(COA!$B$4:$B$28,MATCH(D6,COA!$A$4:$A$28,0)),"# غير موجود")) | J6: =IF(B6="","",IF(ROUND(SUMIF($B$5:$B$64,B6,$H$5:$H$64)-SUMIF($B$5:$B$64,B6,$I$5:$I$64),2)=0,"متوازن","غير متوازن")) | K6: =IF(D6="","",COUNTIFS($D$5:D6,D6)) | L6: =IF(D6="","",D6*1000+K6)
A7: 3 | E7: =IF(D7="","",IFERROR(INDEX(COA!$B$4:$B$28,MATCH(D7,COA!$A$4:$A$28,0)),"# غير موجود")) | J7: =IF(B7="","",IF(ROUND(SUMIF($B$5:$B$64,B7,$H$5:$H$64)-SUMIF($B$5:$B$64,B7,$I$5:$I$64),2)=0,"متوازن","غير متوازن")) | K7: =IF(D7="","",COUNTIFS($D$5:D7,D7)) | L7: =IF(D7="","",D7*1000+K7)
A8: 4 | E8: =IF(D8="","",IFERROR(INDEX(COA!$B$4:$B$28,MATCH(D8,COA!$A$4:$A$28,0)),"# غير موجود")) | J8: =IF(B8="","",IF(ROUND(SUMIF($B$5:$B$64,B8,$H$5:$H$64)-SUMIF($B$5:$B$64,B8,$I$5:$I$64),2)=0,"متوازن","غير متوازن")) | K8: =IF(D8="","",COUNTIFS($D$5:D8,D8)) | L8: =IF(D8="","",D8*1000+K8)
A9: 5 | E9: =IF(D9="","",IFERROR(INDEX(COA!$B$4:$B$28,MATCH(D9,COA!$A$4:$A$28,0)),"# غير موجود")) | J9: =IF(B9="","",IF(ROUND(SUMIF($B$5:$B$64,B9,$H$5:$H$64)-SUMIF($B$5:$B$64,B9,$I$5:$I$64),2)=0,"متوازن","غير متوازن")) | K9: =IF(D9="","",COUNTIFS($D$5:D9,D9)) | L9: =IF(D9="","",D9*1000+K9)
A10: 6 | E10: =IF(D10="","",IFERROR(INDEX(COA!$B$4:$B$28,MATCH(D10,COA!$A$4:$A$28,0)),"# غير موجود")) | J10: =IF(B10="","",IF(ROUND(SUMIF($B$5:$B$64,B10,$H$5:$H$64)-SUMIF($B$5:$B$64,B10,$I$5:$I$64),2)=0,"متوازن","غير متوازن")) | K10: =IF(D10="","",COUNTIFS($D$5:D10,D10)) | L10: =IF(D10="","",D10*1000+K10)
A11: 7 | E11: =IF(D11="","",IFERROR(INDEX(COA!$B$4:$B$28,MATCH(D11,COA!$A$4:$A$28,0)),"# غير موجود")) | J11: =IF(B11="","",IF(ROUND(SUMIF($B$5:$B$64,B11,$H$5:$H$64)-SUMIF($B$5:$B$64,B11,$I$5:$I$64),2)=0,"متوازن","غير متوازن")) | K11: =IF(D11="","",COUNTIFS($D$5:D11,D11)) | L11: =IF(D11="","",D11*1000+K11)
A12: 8 | E12: =IF(D12="","",IFERROR(INDEX(COA!$B$4:$B$28,MATCH(D12,COA!$A$4:$A$28,0)),"# غير موجود")) | J12: =IF(B12="","",IF(ROUND(SUMIF($B$5:$B$64,B12,$H$5:$H$64)-SUMIF($B$5:$B$64,B12,$I$5:$I$64),2)=0,"متوازن","غير متوازن")) | K12: =IF(D12="","",COUNTIFS($D$5:D12,D12)) | L12: =IF(D12="","",D12*1000+K12)
A13: 9 | E13: =IF(D13="","",IFERROR(INDEX(COA!$B$4:$B$28,MATCH(D13,COA!$A$4:$A$28,0)),"# غير موجود")) | J13: =IF(B13="","",IF(ROUND(SUMIF($B$5:$B$64,B13,$H$5:$H$64)-SUMIF($B$5:$B$64,B13,$I$5:$I$64),2)=0,"متوازن","غير متوازن")) | K13: =IF(D13="","",COUNTIFS($D$5:D13,D13)) | L13: =IF(D13="","",D13*1000+K13)
A14: 10 | E14: =IF(D14="","",IFERROR(INDEX(COA!$B$4:$B$28,MATCH(D14,COA!$A$4:$A$28,0)),"# غير موجود")) | J14: =IF(B14="","",IF(ROUND(SUMIF($B$5:$B$64,B14,$H$5:$H$64)-SUMIF($B$5:$B$64,B14,$I$5:$I$64),2)=0,"متوازن","غير متوازن")) | K14: =IF(D14="","",COUNTIFS($D$5:D14,D14)) | L14: =IF(D14="","",D14*1000+K14)
A15: 11 | E15: =IF(D15="","",IFERROR(INDEX(COA!$B$4:$B$28,MATCH(D15,COA!$A$4:$A$28,0)),"# غير موجود")) | J15: =IF(B15="","",IF(ROUND(SUMIF($B$5:$B$64,B15,$H$5:$H$64)-SUMIF($B$5:$B$64,B15,$I$5:$I$64),2)=0,"متوازن","غير متوازن")) | K15: =IF(D15="","",COUNTIFS($D$5:D15,D15)) | L15: =IF(D15="","",D15*1000+K15)
A16: 12 | E16: =IF(D16="","",IFERROR(INDEX(COA!$B$4:$B$28,MATCH(D16,COA!$A$4:$A$28,0)),"# غير موجود")) | J16: =IF(B16="","",IF(ROUND(SUMIF($B$5:$B$64,B16,$H$5:$H$64)-SUMIF($B$5:$B$64,B16,$I$5:$I$64),2)=0,"متوازن","غير متوازن")) | K16: =IF(D16="","",COUNTIFS($D$5:D16,D16)) | L16: =IF(D16="","",D16*1000+K16)
... A64: 60 | E64: =IF(D64="","",IFERROR(INDEX(COA!$B$4:$B$28,MATCH(D64,COA!$A$4:$A$28,0)),"# غير موجود")) | J64: =IF(B64="","",IF(ROUND(SUMIF($B$5:$B$64,B64,$H$5:$H$64)-SUMIF($B$5:$B$64,B64,$I$5:$I$64),2)=0,"متوازن","غير متوازن")) | K64: =IF(D64="","",COUNTIFS($D$5:D64,D64)) | L64: =IF(D64="","",D64*1000+K64)
A66: دليل الألوان: أزرق = خلية إدخال يعدّلها المستخدم | أسود = صيغة محسوبة تلقائياً | أصفر = افتراض/معلمة تدريبية رئيسية | رمادي = عمود مساعد للحسابات (لا يُعدّل)
A67: مثال: قيد رقم 1 بتاريخ 2026-01-05 - إيداع دفعة مقدمة من عميل: 1100 مدين 5,000 / 4100 دائن 5,000 (رقم القيد نفسه لكل من طرفي القيد)

Sheet General Ledger
A1: دفتر الأستاذ - General Ledger
A3: اختر رقم الحساب: | B3: 1100
A4: اسم الحساب: | B4: =IFERROR(INDEX(COA!$B$4:$B$28,MATCH(B3,COA!$A$4:$A$28,0)),"") -> البنك
A5: نوع الحساب: | B5: =IFERROR(INDEX(COA!$C$4:$C$28,MATCH(B3,COA!$A$4:$A$28,0)),"") -> أصل
A6: طبيعة الرصيد: | B6: =IFERROR(INDEX(COA!$D$4:$D$28,MATCH(B3,COA!$A$4:$A$28,0)),"") -> مدين
A8: الرصيد الافتتاحي | B8: إجمالي حركة مدين | C8: إجمالي حركة دائن | D8: الرصيد الختامي
A9: =IF($B$6="مدين",SUMIF('Opening Balances'!$A$5:$A$6,$B$3,'Opening Balances'!$C$5:$C$6)-SUMIF('Opening Balances'!$A$5:$A$6,$B$3,'Opening Balances'!$D$5:$D$6),SUMIF('Opening Balances'!$A$5:$A$6,$B$3,'Opening Balances'!$D$5:$D$6)-SUMIF('Opening Balances'!$A$5:$A$6,$B$3,'Opening Balances'!$C$5:$C$6)) -> 20000000 | B9: =SUMIF(Journal!$D$5:$D$64,$B$3,Journal!$H$5:$H$64) -> 0 | C9: =SUMIF(Journal!$D$5:$D$64,$B$3,Journal!$I$5:$I$64) -> 0 | D9: =IF($B$6="مدين",A9+B9-C9,A9+C9-B9) -> 20000000
A11: تفاصيل حركة الحساب المرحّلة من دفتر اليومية
A12: التاريخ | B12: رقم القيد | C12: البيان | D12: مدين | E12: دائن | F12: الرصيد المتحرك
A13: =IFERROR(INDEX(Journal!$C$5:$C$64,MATCH($B$3*1000+1,Journal!$L$5:$L$64,0)),"") | B13: =IFERROR(INDEX(Journal!$B$5:$B$64,MATCH($B$3*1000+1,Journal!$L$5:$L$64,0)),"") | C13: =IFERROR(INDEX(Journal!$G$5:$G$64,MATCH($B$3*1000+1,Journal!$L$5:$L$64,0)),"") | D13: =IFERROR(INDEX(Journal!$H$5:$H$64,MATCH($B$3*1000+1,Journal!$L$5:$L$64,0)),"") | E13: =IFERROR(INDEX(Journal!$I$5:$I$64,MATCH($B$3*1000+1,Journal!$L$5:$L$64,0)),"") | F13: =IF(D13="","",IF($B$6="مدين",A9+SUMIFS(Journal!$H$5:$H$64,Journal!$D$5:$D$64,$B$3,Journal!$K$5:$K$64,"<="&1)-SUMIFS(Journal!$I$5:$I$64,Journal!$D$5:$D$64,$B$3,Journal!$K$5:$K$64,"<="&1),A9+SUMIFS(Journal!$I$5:$I$64,Journal!$D$5:$D$64,$B$3,Journal!$K$5:$K$64,"<="&1)-SUMIFS(Journal!$H$5:$H$64,Journal!$D$5:$D$64,$B$3,Journal!$K$5:$K$64,"<="&1)))
A14: =IFERROR(INDEX(Journal!$C$5:$C$64,MATCH($B$3*1000+2,Journal!$L$5:$L$64,0)),"") | B14: =IFERROR(INDEX(Journal!$B$5:$B$64,MATCH($B$3*1000+2,Journal!$L$5:$L$64,0)),"") | C14: =IFERROR(INDEX(Journal!$G$5:$G$64,MATCH($B$3*1000+2,Journal!$L$5:$L$64,0)),"") | D14: =IFERROR(INDEX(Journal!$H$5:$H$64,MATCH($B$3*1000+2,Journal!$L$5:$L$64,0)),"") | E14: =IFERROR(INDEX(Journal!$I$5:$I$64,MATCH($B$3*1000+2,Journal!$L$5:$L$64,0)),"") | F14: =IF(D14="","",IF($B$6="مدين",A9+SUMIFS(Journal!$H$5:$H$64,Journal!$D$5:$D$64,$B$3,Journal!$K$5:$K$64,"<="&2)-SUMIFS(Journal!$I$5:$I$64,Journal!$D$5:$D$64,$B$3,Journal!$K$5:$K$64,"<="&2),A9+SUMIFS(Journal!$I$5:$I$64,Journal!$D$5:$D$64,$B$3,Journal!$K$5:$K$64,"<="&2)-SUMIFS(Journal!$H$5:$H$64,Journal!$D$5:$D$64,$B$3,Journal!$K$5:$K$64,"<="&2)))
A15: =IFERROR(INDEX(Journal!$C$5:$C$64,MATCH($B$3*1000+3,Journal!$L$5:$L$64,0)),"") | B15: =IFERROR(INDEX(Journal!$B$5:$B$64,MATCH($B$3*1000+3,Journal!$L$5:$L$64,0)),"") | C15: =IFERROR(INDEX(Journal!$G$5:$G$64,MATCH($B$3*1000+3,Journal!$L$5:$L$64,0)),"") | D15: =IFERROR(INDEX(Journal!$H$5:$H$64,MATCH($B$3*1000+3,Journal!$L$5:$L$64,0)),"") | E15: =IFERROR(INDEX(Journal!$I$5:$I$64,MATCH($B$3*1000+3,Journal!$L$5:$L$64,0)),"") | F15: =IF(D15="","",IF($B$6="مدين",A9+SUMIFS(Journal!$H$5:$H$64,Journal!$D$5:$D$64,$B$3,Journal!$K$5:$K$64,"<="&3)-SUMIFS(Journal!$I$5:$I$64,Journal!$D$5:$D$64,$B$3,Journal!$K$5:$K$64,"<="&3),A9+SUMIFS(Journal!$I$5:$I$64,Journal!$D$5:$D$64,$B$3,Journal!$K$5:$K$64,"<="&3)-SUMIFS(Journal!$H$5:$H$64,Journal!$D$5:$D$64,$B$3,Journal!$K$5:$K$64,"<="&3)))
A16: =IFERROR(INDEX(Journal!$C$5:$C$64,MATCH($B$3*1000+4,Journal!$L$5:$L$64,0)),"") | B16: =IFERROR(INDEX(Journal!$B$5:$B$64,MATCH($B$3*1000+4,Journal!$L$5:$L$64,0)),"") | C16: =IFERROR(INDEX(Journal!$G$5:$G$64,MATCH($B$3*1000+4,Journal!$L$5:$L$64,0)),"") | D16: =IFERROR(INDEX(Journal!$H$5:$H$64,MATCH($B$3*1000+4,Journal!$L$5:$L$64,0)),"") | E16: =IFERROR(INDEX(Journal!$I$5:$I$64,MATCH($B$3*1000+4,Journal!$L$5:$L$64,0)),"") | F16: =IF(D16="","",IF($B$6="مدين",A9+SUMIFS(Journal!$H$5:$H$64,Journal!$D$5:$D$64,$B$3,Journal!$K$5:$K$64,"<="&4)-SUMIFS(Journal!$I$5:$I$64,Journal!$D$5:$D$64,$B$3,Journal!$K$5:$K$64,"<="&4),A9+SUMIFS(Journal!$I$5:$I$64,Journal!$D$5:$D$64,$B$3,Journal!$K$5:$K$64,"<="&4)-SUMIFS(Journal!$H$5:$H$64,Journal!$D$5:$D$64,$B$3,Journal!$K$5:$K$64,"<="&4)))
A17: =IFERROR(INDEX(Journal!$C$5:$C$64,MATCH($B$3*1000+5,Journal!$L$5:$L$64,0)),"") | B17: =IFERROR(INDEX(Journal!$B$5:$B$64,MATCH($B$3*1000+5,Journal!$L$5:$L$64,0)),"") | C17: =IFERROR(INDEX(Journal!$G$5:$G$64,MATCH($B$3*1000+5,Journal!$L$5:$L$64,0)),"") | D17: =IFERROR(INDEX(Journal!$H$5:$H$64,MATCH($B$3*1000+5,Journal!$L$5:$L$64,0)),"") | E17: =IFERROR(INDEX(Journal!$I$5:$I$64,MATCH($B$3*1000+5,Journal!$L$5:$L$64,0)),"") | F17: =IF(D17="","",IF($B$6="مدين",A9+SUMIFS(Journal!$H$5:$H$64,Journal!$D$5:$D$64,$B$3,Journal!$K$5:$K$64,"<="&5)-SUMIFS(Journal!$I$5:$I$64,Journal!$D$5:$D$64,$B$3,Journal!$K$5:$K$64,"<="&5),A9+SUMIFS(Journal!$I$5:$I$64,Journal!$D$5:$D$64,$B$3,Journal!$K$5:$K$64,"<="&5)-SUMIFS(Journal!$H$5:$H$64,Journal!$D$5:$D$64,$B$3,Journal!$K$5:$K$64,"<="&5)))
A18: =IFERROR(INDEX(Journal!$C$5:$C$64,MATCH($B$3*1000+6,Journal!$L$5:$L$64,0)),"") | B18: =IFERROR(INDEX(Journal!$B$5:$B$64,MATCH($B$3*1000+6,Journal!$L$5:$L$64,0)),"") | C18: =IFERROR(INDEX(Journal!$G$5:$G$64,MATCH($B$3*1000+6,Journal!$L$5:$L$64,0)),"") | D18: =IFERROR(INDEX(Journal!$H$5:$H$64,MATCH($B$3*1000+6,Journal!$L$5:$L$64,0)),"") | E18: =IFERROR(INDEX(Journal!$I$5:$I$64,MATCH($B$3*1000+6,Journal!$L$5:$L$64,0)),"") | F18: =IF(D18="","",IF($B$6="مدين",A9+SUMIFS(Journal!$H$5:$H$64,Journal!$D$5:$D$64,$B$3,Journal!$K$5:$K$64,"<="&6)-SUMIFS(Journal!$I$5:$I$64,Journal!$D$5:$D$64,$B$3,Journal!$K$5:$K$64,"<="&6),A9+SUMIFS(Journal!$I$5:$I$64,Journal!$D$5:$D$64,$B$3,Journal!$K$5:$K$64,"<="&6)-SUMIFS(Journal!$H$5:$H$64,Journal!$D$5:$D$64,$B$3,Journal!$K$5:$K$64,"<="&6)))
A19: =IFERROR(INDEX(Journal!$C$5:$C$64,MATCH($B$3*1000+7,Journal!$L$5:$L$64,0)),"") | B19: =IFERROR(INDEX(Journal!$B$5:$B$64,MATCH($B$3*1000+7,Journal!$L$5:$L$64,0)),"") | C19: =IFERROR(INDEX(Journal!$G$5:$G$64,MATCH($B$3*1000+7,Journal!$L$5:$L$64,0)),"") | D19: =IFERROR(INDEX(Journal!$H$5:$H$64,MATCH($B$3*1000+7,Journal!$L$5:$L$64,0)),"") | E19: =IFERROR(INDEX(Journal!$I$5:$I$64,MATCH($B$3*1000+7,Journal!$L$5:$L$64,0)),"") | F19: =IF(D19="","",IF($B$6="مدين",A9+SUMIFS(Journal!$H$5:$H$64,Journal!$D$5:$D$64,$B$3,Journal!$K$5:$K$64,"<="&7)-SUMIFS(Journal!$I$5:$I$64,Journal!$D$5:$D$64,$B$3,Journal!$K$5:$K$64,"<="&7),A9+SUMIFS(Journal!$I$5:$I$64,Journal!$D$5:$D$64,$B$3,Journal!$K$5:$K$64,"<="&7)-SUMIFS(Journal!$H$5:$H$64,Journal!$D$5:$D$64,$B$3,Journal!$K$5:$K$64,"<="&7)))
A20: =IFERROR(INDEX(Journal!$C$5:$C$64,MATCH($B$3*1000+8,Journal!$L$5:$L$64,0)),"") | B20: =IFERROR(INDEX(Journal!$B$5:$B$64,MATCH($B$3*1000+8,Journal!$L$5:$L$64,0)),"") | C20: =IFERROR(INDEX(Journal!$G$5:$G$64,MATCH($B$3*1000+8,Journal!$L$5:$L$64,0)),"") | D20: =IFERROR(INDEX(Journal!$H$5:$H$64,MATCH($B$3*1000+8,Journal!$L$5:$L$64,0)),"") | E20: =IFERROR(INDEX(Journal!$I$5:$I$64,MATCH($B$3*1000+8,Journal!$L$5:$L$64,0)),"") | F20: =IF(D20="","",IF($B$6="مدين",A9+SUMIFS(Journal!$H$5:$H$64,Journal!$D$5:$D$64,$B$3,Journal!$K$5:$K$64,"<="&8)-SUMIFS(Journal!$I$5:$I$64,Journal!$D$5:$D$64,$B$3,Journal!$K$5:$K$64,"<="&8),A9+SUMIFS(Journal!$I$5:$I$64,Journal!$D$5:$D$64,$B$3,Journal!$K$5:$K$64,"<="&8)-SUMIFS(Journal!$H$5:$H$64,Journal!$D$5:$D$64,$B$3,Journal!$K$5:$K$64,"<="&8)))
A21: =IFERROR(INDEX(Journal!$C$5:$C$64,MATCH($B$3*1000+9,Journal!$L$5:$L$64,0)),"") | B21: =IFERROR(INDEX(Journal!$B$5:$B$64,MATCH($B$3*1000+9,Journal!$L$5:$L$64,0)),"") | C21: =IFERROR(INDEX(Journal!$G$5:$G$64,MATCH($B$3*1000+9,Journal!$L$5:$L$64,0)),"") | D21: =IFERROR(INDEX(Journal!$H$5:$H$64,MATCH($B$3*1000+9,Journal!$L$5:$L$64,0)),"") | E21: =IFERROR(INDEX(Journal!$I$5:$I$64,MATCH($B$3*1000+9,Journal!$L$5:$L$64,0)),"") | F21: =IF(D21="","",IF($B$6="مدين",A9+SUMIFS(Journal!$H$5:$H$64,Journal!$D$5:$D$64,$B$3,Journal!$K$5:$K$64,"<="&9)-SUMIFS(Journal!$I$5:$I$64,Journal!$D$5:$D$64,$B$3,Journal!$K$5:$K$64,"<="&9),A9+SUMIFS(Journal!$I$5:$I$64,Journal!$D$5:$D$64,$B$3,Journal!$K$5:$K$64,"<="&9)-SUMIFS(Journal!$H$5:$H$64,Journal!$D$5:$D$64,$B$3,Journal!$K$5:$K$64,"<="&9)))
A22: =IFERROR(INDEX(Journal!$C$5:$C$64,MATCH($B$3*1000+10,Journal!$L$5:$L$64,0)),"") | B22: =IFERROR(INDEX(Journal!$B$5:$B$64,MATCH($B$3*1000+10,Journal!$L$5:$L$64,0)),"") | C22: =IFERROR(INDEX(Journal!$G$5:$G$64,MATCH($B$3*1000+10,Journal!$L$5:$L$64,0)),"") | D22: =IFERROR(INDEX(Journal!$H$5:$H$64,MATCH($B$3*1000+10,Journal!$L$5:$L$64,0)),"") | E22: =IFERROR(INDEX(Journal!$I$5:$I$64,MATCH($B$3*1000+10,Journal!$L$5:$L$64,0)),"") | F22: =IF(D22="","",IF($B$6="مدين",A9+SUMIFS(Journal!$H$5:$H$64,Journal!$D$5:$D$64,$B$3,Journal!$K$5:$K$64,"<="&10)-SUMIFS(Journal!$I$5:$I$64,Journal!$D$5:$D$64,$B$3,Journal!$K$5:$K$64,"<="&10),A9+SUMIFS(Journal!$I$5:$I$64,Journal!$D$5:$D$64,$B$3,Journal!$K$5:$K$64,"<="&10)-SUMIFS(Journal!$H$5:$H$64,Journal!$D$5:$D$64,$B$3,Journal!$K$5:$K$64,"<="&10)))
A23: =IFERROR(INDEX(Journal!$C$5:$C$64,MATCH($B$3*1000+11,Journal!$L$5:$L$64,0)),"") | B23: =IFERROR(INDEX(Journal!$B$5:$B$64,MATCH($B$3*1000+11,Journal!$L$5:$L$64,0)),"") | C23: =IFERROR(INDEX(Journal!$G$5:$G$64,MATCH($B$3*1000+11,Journal!$L$5:$L$64,0)),"") | D23: =IFERROR(INDEX(Journal!$H$5:$H$64,MATCH($B$3*1000+11,Journal!$L$5:$L$64,0)),"") | E23: =IFERROR(INDEX(Journal!$I$5:$I$64,MATCH($B$3*1000+11,Journal!$L$5:$L$64,0)),"") | F23: =IF(D23="","",IF($B$6="مدين",A9+SUMIFS(Journal!$H$5:$H$64,Journal!$D$5:$D$64,$B$3,Journal!$K$5:$K$64,"<="&11)-SUMIFS(Journal!$I$5:$I$64,Journal!$D$5:$D$64,$B$3,Journal!$K$5:$K$64,"<="&11),A9+SUMIFS(Journal!$I$5:$I$64,Journal!$D$5:$D$64,$B$3,Journal!$K$5:$K$64,"<="&11)-SUMIFS(Journal!$H$5:$H$64,Journal!$D$5:$D$64,$B$3,Journal!$K$5:$K$64,"<="&11)))
A24: =IFERROR(INDEX(Journal!$C$5:$C$64,MATCH($B$3*1000+12,Journal!$L$5:$L$64,0)),"") | B24: =IFERROR(INDEX(Journal!$B$5:$B$64,MATCH($B$3*1000+12,Journal!$L$5:$L$64,0)),"") | C24: =IFERROR(INDEX(Journal!$G$5:$G$64,MATCH($B$3*1000+12,Journal!$L$5:$L$64,0)),"") | D24: =IFERROR(INDEX(Journal!$H$5:$H$64,MATCH($B$3*1000+12,Journal!$L$5:$L$64,0)),"") | E24: =IFERROR(INDEX(Journal!$I$5:$I$64,MATCH($B$3*1000+12,Journal!$L$5:$L$64,0)),"") | F24: =IF(D24="","",IF($B$6="مدين",A9+SUMIFS(Journal!$H$5:$H$64,Journal!$D$5:$D$64,$B$3,Journal!$K$5:$K$64,"<="&12)-SUMIFS(Journal!$I$5:$I$64,Journal!$D$5:$D$64,$B$3,Journal!$K$5:$K$64,"<="&12),A9+SUMIFS(Journal!$I$5:$I$64,Journal!$D$5:$D$64,$B$3,Journal!$K$5:$K$64,"<="&12)-SUMIFS(Journal!$H$5:$H$64,Journal!$D$5:$D$64,$B$3,Journal!$K$5:$K$64,"<="&12)))
A25: =IFERROR(INDEX(Journal!$C$5:$C$64,MATCH($B$3*1000+13,Journal!$L$5:$L$64,0)),"") | B25: =IFERROR(INDEX(Journal!$B$5:$B$64,MATCH($B$3*1000+13,Journal!$L$5:$L$64,0)),"") | C25: =IFERROR(INDEX(Journal!$G$5:$G$64,MATCH($B$3*1000+13,Journal!$L$5:$L$64,0)),"") | D25: =IFERROR(INDEX(Journal!$H$5:$H$64,MATCH($B$3*1000+13,Journal!$L$5:$L$64,0)),"") | E25: =IFERROR(INDEX(Journal!$I$5:$I$64,MATCH($B$3*1000+13,Journal!$L$5:$L$64,0)),"") | F25: =IF(D25="","",IF($B$6="مدين",A9+SUMIFS(Journal!$H$5:$H$64,Journal!$D$5:$D$64,$B$3,Journal!$K$5:$K$64,"<="&13)-SUMIFS(Journal!$I$5:$I$64,Journal!$D$5:$D$64,$B$3,Journal!$K$5:$K$64,"<="&13),A9+SUMIFS(Journal!$I$5:$I$64,Journal!$D$5:$D$64,$B$3,Journal!$K$5:$K$64,"<="&13)-SUMIFS(Journal!$H$5:$H$64,Journal!$D$5:$D$64,$B$3,Journal!$K$5:$K$64,"<="&13)))
A26: =IFERROR(INDEX(Journal!$C$5:$C$64,MATCH($B$3*1000+14,Journal!$L$5:$L$64,0)),"") | B26: =IFERROR(INDEX(Journal!$B$5:$B$64,MATCH($B$3*1000+14,Journal!$L$5:$L$64,0)),"") | C26: =IFERROR(INDEX(Journal!$G$5:$G$64,MATCH($B$3*1000+14,Journal!$L$5:$L$64,0)),"") | D26: =IFERROR(INDEX(Journal!$H$5:$H$64,MATCH($B$3*1000+14,Journal!$L$5:$L$64,0)),"") | E26: =IFERROR(INDEX(Journal!$I$5:$I$64,MATCH($B$3*1000+14,Journal!$L$5:$L$64,0)),"") | F26: =IF(D26="","",IF($B$6="مدين",A9+SUMIFS(Journal!$H$5:$H$64,Journal!$D$5:$D$64,$B$3,Journal!$K$5:$K$64,"<="&14)-SUMIFS(Journal!$I$5:$I$64,Journal!$D$5:$D$64,$B$3,Journal!$K$5:$K$64,"<="&14),A9+SUMIFS(Journal!$I$5:$I$64,Journal!$D$5:$D$64,$B$3,Journal!$K$5:$K$64,"<="&14)-SUMIFS(Journal!$H$5:$H$64,Journal!$D$5:$D$64,$B$3,Journal!$K$5:$K$64,"<="&14)))
A27: =IFERROR(INDEX(Journal!$C$5:$C$64,MATCH($B$3*1000+15,Journal!$L$5:$L$64,0)),"") | B27: =IFERROR(INDEX(Journal!$B$5:$B$64,MATCH($B$3*1000+15,Journal!$L$5:$L$64,0)),"") | C27: =IFERROR(INDEX(Journal!$G$5:$G$64,MATCH($B$3*1000+15,Journal!$L$5:$L$64,0)),"") | D27: =IFERROR(INDEX(Journal!$H$5:$H$64,MATCH($B$3*1000+15,Journal!$L$5:$L$64,0)),"") | E27: =IFERROR(INDEX(Journal!$I$5:$I$64,MATCH($B$3*1000+15,Journal!$L$5:$L$64,0)),"") | F27: =IF(D27="","",IF($B$6="مدين",A9+SUMIFS(Journal!$H$5:$H$64,Journal!$D$5:$D$64,$B$3,Journal!$K$5:$K$64,"<="&15)-SUMIFS(Journal!$I$5:$I$64,Journal!$D$5:$D$64,$B$3,Journal!$K$5:$K$64,"<="&15),A9+SUMIFS(Journal!$I$5:$I$64,Journal!$D$5:$D$64,$B$3,Journal!$K$5:$K$64,"<="&15)-SUMIFS(Journal!$H$5:$H$64,Journal!$D$5:$D$64,$B$3,Journal!$K$5:$K$64,"<="&15)))
A28: =IFERROR(INDEX(Journal!$C$5:$C$64,MATCH($B$3*1000+16,Journal!$L$5:$L$64,0)),"") | B28: =IFERROR(INDEX(Journal!$B$5:$B$64,MATCH($B$3*1000+16,Journal!$L$5:$L$64,0)),"") | C28: =IFERROR(INDEX(Journal!$G$5:$G$64,MATCH($B$3*1000+16,Journal!$L$5:$L$64,0)),"") | D28: =IFERROR(INDEX(Journal!$H$5:$H$64,MATCH($B$3*1000+16,Journal!$L$5:$L$64,0)),"") | E28: =IFERROR(INDEX(Journal!$I$5:$I$64,MATCH($B$3*1000+16,Journal!$L$5:$L$64,0)),"") | F28: =IF(D28="","",IF($B$6="مدين",A9+SUMIFS(Journal!$H$5:$H$64,Journal!$D$5:$D$64,$B$3,Journal!$K$5:$K$64,"<="&16)-SUMIFS(Journal!$I$5:$I$64,Journal!$D$5:$D$64,$B$3,Journal!$K$5:$K$64,"<="&16),A9+SUMIFS(Journal!$I$5:$I$64,Journal!$D$5:$D$64,$B$3,Journal!$K$5:$K$64,"<="&16)-SUMIFS(Journal!$H$5:$H$64,Journal!$D$5:$D$64,$B$3,Journal!$K$5:$K$64,"<="&16)))
A29: =IFERROR(INDEX(Journal!$C$5:$C$64,MATCH($B$3*1000+17,Journal!$L$5:$L$64,0)),"") | B29: =IFERROR(INDEX(Journal!$B$5:$B$64,MATCH($B$3*1000+17,Journal!$L$5:$L$64,0)),"") | C29: =IFERROR(INDEX(Journal!$G$5:$G$64,MATCH($B$3*1000+17,Journal!$L$5:$L$64,0)),"") | D29: =IFERROR(INDEX(Journal!$H$5:$H$64,MATCH($B$3*1000+17,Journal!$L$5:$L$64,0)),"") | E29: =IFERROR(INDEX(Journal!$I$5:$I$64,MATCH($B$3*1000+17,Journal!$L$5:$L$64,0)),"") | F29: =IF(D29="","",IF($B$6="مدين",A9+SUMIFS(Journal!$H$5:$H$64,Journal!$D$5:$D$64,$B$3,Journal!$K$5:$K$64,"<="&17)-SUMIFS(Journal!$I$5:$I$64,Journal!$D$5:$D$64,$B$3,Journal!$K$5:$K$64,"<="&17),A9+SUMIFS(Journal!$I$5:$I$64,Journal!$D$5:$D$64,$B$3,Journal!$K$5:$K$64,"<="&17)-SUMIFS(Journal!$H$5:$H$64,Journal!$D$5:$D$64,$B$3,Journal!$K$5:$K$64,"<="&17)))
A30: =IFERROR(INDEX(Journal!$C$5:$C$64,MATCH($B$3*1000+18,Journal!$L$5:$L$64,0)),"") | B30: =IFERROR(INDEX(Journal!$B$5:$B$64,MATCH($B$3*1000+18,Journal!$L$5:$L$64,0)),"") | C30: =IFERROR(INDEX(Journal!$G$5:$G$64,MATCH($B$3*1000+18,Journal!$L$5:$L$64,0)),"") | D30: =IFERROR(INDEX(Journal!$H$5:$H$64,MATCH($B$3*1000+18,Journal!$L$5:$L$64,0)),"") | E30: =IFERROR(INDEX(Journal!$I$5:$I$64,MATCH($B$3*1000+18,Journal!$L$5:$L$64,0)),"") | F30: =IF(D30="","",IF($B$6="مدين",A9+SUMIFS(Journal!$H$5:$H$64,Journal!$D$5:$D$64,$B$3,Journal!$K$5:$K$64,"<="&18)-SUMIFS(Journal!$I$5:$I$64,Journal!$D$5:$D$64,$B$3,Journal!$K$5:$K$64,"<="&18),A9+SUMIFS(Journal!$I$5:$I$64,Journal!$D$5:$D$64,$B$3,Journal!$K$5:$K$64,"<="&18)-SUMIFS(Journal!$H$5:$H$64,Journal!$D$5:$D$64,$B$3,Journal!$K$5:$K$64,"<="&18)))
A31: =IFERROR(INDEX(Journal!$C$5:$C$64,MATCH($B$3*1000+19,Journal!$L$5:$L$64,0)),"") | B31: =IFERROR(INDEX(Journal!$B$5:$B$64,MATCH($B$3*1000+19,Journal!$L$5:$L$64,0)),"") | C31: =IFERROR(INDEX(Journal!$G$5:$G$64,MATCH($B$3*1000+19,Journal!$L$5:$L$64,0)),"") | D31: =IFERROR(INDEX(Journal!$H$5:$H$64,MATCH($B$3*1000+19,Journal!$L$5:$L$64,0)),"") | E31: =IFERROR(INDEX(Journal!$I$5:$I$64,MATCH($B$3*1000+19,Journal!$L$5:$L$64,0)),"") | F31: =IF(D31="","",IF($B$6="مدين",A9+SUMIFS(Journal!$H$5:$H$64,Journal!$D$5:$D$64,$B$3,Journal!$K$5:$K$64,"<="&19)-SUMIFS(Journal!$I$5:$I$64,Journal!$D$5:$D$64,$B$3,Journal!$K$5:$K$64,"<="&19),A9+SUMIFS(Journal!$I$5:$I$64,Journal!$D$5:$D$64,$B$3,Journal!$K$5:$K$64,"<="&19)-SUMIFS(Journal!$H$5:$H$64,Journal!$D$5:$D$64,$B$3,Journal!$K$5:$K$64,"<="&19)))
A32: =IFERROR(INDEX(Journal!$C$5:$C$64,MATCH($B$3*1000+20,Journal!$L$5:$L$64,0)),"") | B32: =IFERROR(INDEX(Journal!$B$5:$B$64,MATCH($B$3*1000+20,Journal!$L$5:$L$64,0)),"") | C32: =IFERROR(INDEX(Journal!$G$5:$G$64,MATCH($B$3*1000+20,Journal!$L$5:$L$64,0)),"") | D32: =IFERROR(INDEX(Journal!$H$5:$H$64,MATCH($B$3*1000+20,Journal!$L$5:$L$64,0)),"") | E32: =IFERROR(INDEX(Journal!$I$5:$I$64,MATCH($B$3*1000+20,Journal!$L$5:$L$64,0)),"") | F32: =IF(D32="","",IF($B$6="مدين",A9+SUMIFS(Journal!$H$5:$H$64,Journal!$D$5:$D$64,$B$3,Journal!$K$5:$K$64,"<="&20)-SUMIFS(Journal!$I$5:$I$64,Journal!$D$5:$D$64,$B$3,Journal!$K$5:$K$64,"<="&20),A9+SUMIFS(Journal!$I$5:$I$64,Journal!$D$5:$D$64,$B$3,Journal!$K$5:$K$64,"<="&20)-SUMIFS(Journal!$H$5:$H$64,Journal!$D$5:$D$64,$B$3,Journal!$K$5:$K$64,"<="&20)))
A33: =IFERROR(INDEX(Journal!$C$5:$C$64,MATCH($B$3*1000+21,Journal!$L$5:$L$64,0)),"") | B33: =IFERROR(INDEX(Journal!$B$5:$B$64,MATCH($B$3*1000+21,Journal!$L$5:$L$64,0)),"") | C33: =IFERROR(INDEX(Journal!$G$5:$G$64,MATCH($B$3*1000+21,Journal!$L$5:$L$64,0)),"") | D33: =IFERROR(INDEX(Journal!$H$5:$H$64,MATCH($B$3*1000+21,Journal!$L$5:$L$64,0)),"") | E33: =IFERROR(INDEX(Journal!$I$5:$I$64,MATCH($B$3*1000+21,Journal!$L$5:$L$64,0)),"") | F33: =IF(D33="","",IF($B$6="مدين",A9+SUMIFS(Journal!$H$5:$H$64,Journal!$D$5:$D$64,$B$3,Journal!$K$5:$K$64,"<="&21)-SUMIFS(Journal!$I$5:$I$64,Journal!$D$5:$D$64,$B$3,Journal!$K$5:$K$64,"<="&21),A9+SUMIFS(Journal!$I$5:$I$64,Journal!$D$5:$D$64,$B$3,Journal!$K$5:$K$64,"<="&21)-SUMIFS(Journal!$H$5:$H$64,Journal!$D$5:$D$64,$B$3,Journal!$K$5:$K$64,"<="&21)))
A34: =IFERROR(INDEX(Journal!$C$5:$C$64,MATCH($B$3*1000+22,Journal!$L$5:$L$64,0)),"") | B34: =IFERROR(INDEX(Journal!$B$5:$B$64,MATCH($B$3*1000+22,Journal!$L$5:$L$64,0)),"") | C34: =IFERROR(INDEX(Journal!$G$5:$G$64,MATCH($B$3*1000+22,Journal!$L$5:$L$64,0)),"") | D34: =IFERROR(INDEX(Journal!$H$5:$H$64,MATCH($B$3*1000+22,Journal!$L$5:$L$64,0)),"") | E34: =IFERROR(INDEX(Journal!$I$5:$I$64,MATCH($B$3*1000+22,Journal!$L$5:$L$64,0)),"") | F34: =IF(D34="","",IF($B$6="مدين",A9+SUMIFS(Journal!$H$5:$H$64,Journal!$D$5:$D$64,$B$3,Journal!$K$5:$K$64,"<="&22)-SUMIFS(Journal!$I$5:$I$64,Journal!$D$5:$D$64,$B$3,Journal!$K$5:$K$64,"<="&22),A9+SUMIFS(Journal!$I$5:$I$64,Journal!$D$5:$D$64,$B$3,Journal!$K$5:$K$64,"<="&22)-SUMIFS(Journal!$H$5:$H$64,Journal!$D$5:$D$64,$B$3,Journal!$K$5:$K$64,"<="&22)))
A35: =IFERROR(INDEX(Journal!$C$5:$C$64,MATCH($B$3*1000+23,Journal!$L$5:$L$64,0)),"") | B35: =IFERROR(INDEX(Journal!$B$5:$B$64,MATCH($B$3*1000+23,Journal!$L$5:$L$64,0)),"") | C35: =IFERROR(INDEX(Journal!$G$5:$G$64,MATCH($B$3*1000+23,Journal!$L$5:$L$64,0)),"") | D35: =IFERROR(INDEX(Journal!$H$5:$H$64,MATCH($B$3*1000+23,Journal!$L$5:$L$64,0)),"") | E35: =IFERROR(INDEX(Journal!$I$5:$I$64,MATCH($B$3*1000+23,Journal!$L$5:$L$64,0)),"") | F35: =IF(D35="","",IF($B$6="مدين",A9+SUMIFS(Journal!$H$5:$H$64,Journal!$D$5:$D$64,$B$3,Journal!$K$5:$K$64,"<="&23)-SUMIFS(Journal!$I$5:$I$64,Journal!$D$5:$D$64,$B$3,Journal!$K$5:$K$64,"<="&23),A9+SUMIFS(Journal!$I$5:$I$64,Journal!$D$5:$D$64,$B$3,Journal!$K$5:$K$64,"<="&23)-SUMIFS(Journal!$H$5:$H$64,Journal!$D$5:$D$64,$B$3,Journal!$K$5:$K$64,"<="&23)))
A36: =IFERROR(INDEX(Journal!$C$5:$C$64,MATCH($B$3*1000+24,Journal!$L$5:$L$64,0)),"") | B36: =IFERROR(INDEX(Journal!$B$5:$B$64,MATCH($B$3*1000+24,Journal!$L$5:$L$64,0)),"") | C36: =IFERROR(INDEX(Journal!$G$5:$G$64,MATCH($B$3*1000+24,Journal!$L$5:$L$64,0)),"") | D36: =IFERROR(INDEX(Journal!$H$5:$H$64,MATCH($B$3*1000+24,Journal!$L$5:$L$64,0)),"") | E36: =IFERROR(INDEX(Journal!$I$5:$I$64,MATCH($B$3*1000+24,Journal!$L$5:$L$64,0)),"") | F36: =IF(D36="","",IF($B$6="مدين",A9+SUMIFS(Journal!$H$5:$H$64,Journal!$D$5:$D$64,$B$3,Journal!$K$5:$K$64,"<="&24)-SUMIFS(Journal!$I$5:$I$64,Journal!$D$5:$D$64,$B$3,Journal!$K$5:$K$64,"<="&24),A9+SUMIFS(Journal!$I$5:$I$64,Journal!$D$5:$D$64,$B$3,Journal!$K$5:$K$64,"<="&24)-SUMIFS(Journal!$H$5:$H$64,Journal!$D$5:$D$64,$B$3,Journal!$K$5:$K$64,"<="&24)))
A37: =IFERROR(INDEX(Journal!$C$5:$C$64,MATCH($B$3*1000+25,Journal!$L$5:$L$64,0)),"") | B37: =IFERROR(INDEX(Journal!$B$5:$B$64,MATCH($B$3*1000+25,Journal!$L$5:$L$64,0)),"") | C37: =IFERROR(INDEX(Journal!$G$5:$G$64,MATCH($B$3*1000+25,Journal!$L$5:$L$64,0)),"") | D37: =IFERROR(INDEX(Journal!$H$5:$H$64,MATCH($B$3*1000+25,Journal!$L$5:$L$64,0)),"") | E37: =IFERROR(INDEX(Journal!$I$5:$I$64,MATCH($B$3*1000+25,Journal!$L$5:$L$64,0)),"") | F37: =IF(D37="","",IF($B$6="مدين",A9+SUMIFS(Journal!$H$5:$H$64,Journal!$D$5:$D$64,$B$3,Journal!$K$5:$K$64,"<="&25)-SUMIFS(Journal!$I$5:$I$64,Journal!$D$5:$D$64,$B$3,Journal!$K$5:$K$64,"<="&25),A9+SUMIFS(Journal!$I$5:$I$64,Journal!$D$5:$D$64,$B$3,Journal!$K$5:$K$64,"<="&25)-SUMIFS(Journal!$H$5:$H$64,Journal!$D$5:$D$64,$B$3,Journal!$K$5:$K$64,"<="&25)))
A38: =IFERROR(INDEX(Journal!$C$5:$C$64,MATCH($B$3*1000+26,Journal!$L$5:$L$64,0)),"") | B38: =IFERROR(INDEX(Journal!$B$5:$B$64,MATCH($B$3*1000+26,Journal!$L$5:$L$64,0)),"") | C38: =IFERROR(INDEX(Journal!$G$5:$G$64,MATCH($B$3*1000+26,Journal!$L$5:$L$64,0)),"") | D38: =IFERROR(INDEX(Journal!$H$5:$H$64,MATCH($B$3*1000+26,Journal!$L$5:$L$64,0)),"") | E38: =IFERROR(INDEX(Journal!$I$5:$I$64,MATCH($B$3*1000+26,Journal!$L$5:$L$64,0)),"") | F38: =IF(D38="","",IF($B$6="مدين",A9+SUMIFS(Journal!$H$5:$H$64,Journal!$D$5:$D$64,$B$3,Journal!$K$5:$K$64,"<="&26)-SUMIFS(Journal!$I$5:$I$64,Journal!$D$5:$D$64,$B$3,Journal!$K$5:$K$64,"<="&26),A9+SUMIFS(Journal!$I$5:$I$64,Journal!$D$5:$D$64,$B$3,Journal!$K$5:$K$64,"<="&26)-SUMIFS(Journal!$H$5:$H$64,Journal!$D$5:$D$64,$B$3,Journal!$K$5:$K$64,"<="&26)))
A39: =IFERROR(INDEX(Journal!$C$5:$C$64,MATCH($B$3*1000+27,Journal!$L$5:$L$64,0)),"") | B39: =IFERROR(INDEX(Journal!$B$5:$B$64,MATCH($B$3*1000+27,Journal!$L$5:$L$64,0)),"") | C39: =IFERROR(INDEX(Journal!$G$5:$G$64,MATCH($B$3*1000+27,Journal!$L$5:$L$64,0)),"") | D39: =IFERROR(INDEX(Journal!$H$5:$H$64,MATCH($B$3*1000+27,Journal!$L$5:$L$64,0)),"") | E39: =IFERROR(INDEX(Journal!$I$5:$I$64,MATCH($B$3*1000+27,Journal!$L$5:$L$64,0)),"") | F39: =IF(D39="","",IF($B$6="مدين",A9+SUMIFS(Journal!$H$5:$H$64,Journal!$D$5:$D$64,$B$3,Journal!$K$5:$K$64,"<="&27)-SUMIFS(Journal!$I$5:$I$64,Journal!$D$5:$D$64,$B$3,Journal!$K$5:$K$64,"<="&27),A9+SUMIFS(Journal!$I$5:$I$64,Journal!$D$5:$D$64,$B$3,Journal!$K$5:$K$64,"<="&27)-SUMIFS(Journal!$H$5:$H$64,Journal!$D$5:$D$64,$B$3,Journal!$K$5:$K$64,"<="&27)))
A40: =IFERROR(INDEX(Journal!$C$5:$C$64,MATCH($B$3*1000+28,Journal!$L$5:$L$64,0)),"") | B40: =IFERROR(INDEX(Journal!$B$5:$B$64,MATCH($B$3*1000+28,Journal!$L$5:$L$64,0)),"") | C40: =IFERROR(INDEX(Journal!$G$5:$G$64,MATCH($B$3*1000+28,Journal!$L$5:$L$64,0)),"") | D40: =IFERROR(INDEX(Journal!$H$5:$H$64,MATCH($B$3*1000+28,Journal!$L$5:$L$64,0)),"") | E40: =IFERROR(INDEX(Journal!$I$5:$I$64,MATCH($B$3*1000+28,Journal!$L$5:$L$64,0)),"") | F40: =IF(D40="","",IF($B$6="مدين",A9+SUMIFS(Journal!$H$5:$H$64,Journal!$D$5:$D$64,$B$3,Journal!$K$5:$K$64,"<="&28)-SUMIFS(Journal!$I$5:$I$64,Journal!$D$5:$D$64,$B$3,Journal!$K$5:$K$64,"<="&28),A9+SUMIFS(Journal!$I$5:$I$64,Journal!$D$5:$D$64,$B$3,Journal!$K$5:$K$64,"<="&28)-SUMIFS(Journal!$H$5:$H$64,Journal!$D$5:$D$64,$B$3,Journal!$K$5:$K$64,"<="&28)))
A41: =IFERROR(INDEX(Journal!$C$5:$C$64,MATCH($B$3*1000+29,Journal!$L$5:$L$64,0)),"") | B41: =IFERROR(INDEX(Journal!$B$5:$B$64,MATCH($B$3*1000+29,Journal!$L$5:$L$64,0)),"") | C41: =IFERROR(INDEX(Journal!$G$5:$G$64,MATCH($B$3*1000+29,Journal!$L$5:$L$64,0)),"") | D41: =IFERROR(INDEX(Journal!$H$5:$H$64,MATCH($B$3*1000+29,Journal!$L$5:$L$64,0)),"") | E41: =IFERROR(INDEX(Journal!$I$5:$I$64,MATCH($B$3*1000+29,Journal!$L$5:$L$64,0)),"") | F41: =IF(D41="","",IF($B$6="مدين",A9+SUMIFS(Journal!$H$5:$H$64,Journal!$D$5:$D$64,$B$3,Journal!$K$5:$K$64,"<="&29)-SUMIFS(Journal!$I$5:$I$64,Journal!$D$5:$D$64,$B$3,Journal!$K$5:$K$64,"<="&29),A9+SUMIFS(Journal!$I$5:$I$64,Journal!$D$5:$D$64,$B$3,Journal!$K$5:$K$64,"<="&29)-SUMIFS(Journal!$H$5:$H$64,Journal!$D$5:$D$64,$B$3,Journal!$K$5:$K$64,"<="&29)))
A42: =IFERROR(INDEX(Journal!$C$5:$C$64,MATCH($B$3*1000+30,Journal!$L$5:$L$64,0)),"") | B42: =IFERROR(INDEX(Journal!$B$5:$B$64,MATCH($B$3*1000+30,Journal!$L$5:$L$64,0)),"") | C42: =IFERROR(INDEX(Journal!$G$5:$G$64,MATCH($B$3*1000+30,Journal!$L$5:$L$64,0)),"") | D42: =IFERROR(INDEX(Journal!$H$5:$H$64,MATCH($B$3*1000+30,Journal!$L$5:$L$64,0)),"") | E42: =IFERROR(INDEX(Journal!$I$5:$I$64,MATCH($B$3*1000+30,Journal!$L$5:$L$64,0)),"") | F42: =IF(D42="","",IF($B$6="مدين",A9+SUMIFS(Journal!$H$5:$H$64,Journal!$D$5:$D$64,$B$3,Journal!$K$5:$K$64,"<="&30)-SUMIFS(Journal!$I$5:$I$64,Journal!$D$5:$D$64,$B$3,Journal!$K$5:$K$64,"<="&30),A9+SUMIFS(Journal!$I$5:$I$64,Journal!$D$5:$D$64,$B$3,Journal!$K$5:$K$64,"<="&30)-SUMIFS(Journal!$H$5:$H$64,Journal!$D$5:$D$64,$B$3,Journal!$K$5:$K$64,"<="&30)))
A43: =IFERROR(INDEX(Journal!$C$5:$C$64,MATCH($B$3*1000+31,Journal!$L$5:$L$64,0)),"") | B43: =IFERROR(INDEX(Journal!$B$5:$B$64,MATCH($B$3*1000+31,Journal!$L$5:$L$64,0)),"") | C43: =IFERROR(INDEX(Journal!$G$5:$G$64,MATCH($B$3*1000+31,Journal!$L$5:$L$64,0)),"") | D43: =IFERROR(INDEX(Journal!$H$5:$H$64,MATCH($B$3*1000+31,Journal!$L$5:$L$64,0)),"") | E43: =IFERROR(INDEX(Journal!$I$5:$I$64,MATCH($B$3*1000+31,Journal!$L$5:$L$64,0)),"") | F43: =IF(D43="","",IF($B$6="مدين",A9+SUMIFS(Journal!$H$5:$H$64,Journal!$D$5:$D$64,$B$3,Journal!$K$5:$K$64,"<="&31)-SUMIFS(Journal!$I$5:$I$64,Journal!$D$5:$D$64,$B$3,Journal!$K$5:$K$64,"<="&31),A9+SUMIFS(Journal!$I$5:$I$64,Journal!$D$5:$D$64,$B$3,Journal!$K$5:$K$64,"<="&31)-SUMIFS(Journal!$H$5:$H$64,Journal!$D$5:$D$64,$B$3,Journal!$K$5:$K$64,"<="&31)))
...

Sheet Trial Balance
A1: ميزان المراجعة - Trial Balance
A2: كما في 2026-01-31
A4: رقم الحساب | B4: اسم الحساب | C4: افتتاحي مدين | D4: افتتاحي دائن | E4: حركة مدين | F4: حركة دائن | G4: ختامي مدين | H4: ختامي دائن
A5: =COA!$A$4 -> 1100 | B5: =COA!$B$4 -> البنك | C5: =SUMIF('Opening Balances'!$A$5:$A$6,A5,'Opening Balances'!$C$5:$C$6) -> 20000000 | D5: =SUMIF('Opening Balances'!$A$5:$A$6,A5,'Opening Balances'!$D$5:$D$6) -> 0 | E5: =SUMIF(Journal!$D$5:$D$64,A5,Journal!$H$5:$H$64) -> 0 | F5: =SUMIF(Journal!$D$5:$D$64,A5,Journal!$I$5:$I$64) -> 0 | G5: =IF((C5+E5)-(D5+F5)>=0,(C5+E5)-(D5+F5),0) -> 20000000 | H5: =IF((C5+E5)-(D5+F5)<0,-((C5+E5)-(D5+F5)),0) -> 0
A6: =COA!$A$5 -> 1200 | B6: =COA!$B$5 -> العملاء (المدينون) | C6: =SUMIF('Opening Balances'!$A$5:$A$6,A6,'Opening Balances'!$C$5:$C$6) -> 0 | D6: =SUMIF('Opening Balances'!$A$5:$A$6,A6,'Opening Balances'!$D$5:$D$6) -> 0 | E6: =SUMIF(Journal!$D$5:$D$64,A6,Journal!$H$5:$H$64) -> 0 | F6: =SUMIF(Journal!$D$5:$D$64,A6,Journal!$I$5:$I$64) -> 0 | G6: =IF((C6+E6)-(D6+F6)>=0,(C6+E6)-(D6+F6),0) -> 0 | H6: =IF((C6+E6)-(D6+F6)<0,-((C6+E6)-(D6+F6)),0) -> 0
A7: =COA!$A$6 -> 1300 | B7: =COA!$B$6 -> المخزون | C7: =SUMIF('Opening Balances'!$A$5:$A$6,A7,'Opening Balances'!$C$5:$C$6) -> 0 | D7: =SUMIF('Opening Balances'!$A$5:$A$6,A7,'Opening Balances'!$D$5:$D$6) -> 0 | E7: =SUMIF(Journal!$D$5:$D$64,A7,Journal!$H$5:$H$64) -> 0 | F7: =SUMIF(Journal!$D$5:$D$64,A7,Journal!$I$5:$I$64) -> 0 | G7: =IF((C7+E7)-(D7+F7)>=0,(C7+E7)-(D7+F7),0) -> 0 | H7: =IF((C7+E7)-(D7+F7)<0,-((C7+E7)-(D7+F7)),0) -> 0
A8: =COA!$A$7 -> 1400 | B8: =COA!$B$7 -> معدات وأجهزة | C8: =SUMIF('Opening Balances'!$A$5:$A$6,A8,'Opening Balances'!$C$5:$C$6) -> 0 | D8: =SUMIF('Opening Balances'!$A$5:$A$6,A8,'Opening Balances'!$D$5:$D$6) -> 0 | E8: =SUMIF(Journal!$D$5:$D$64,A8,Journal!$H$5:$H$64) -> 0 | F8: =SUMIF(Journal!$D$5:$D$64,A8,Journal!$I$5:$I$64) -> 0 | G8: =IF((C8+E8)-(D8+F8)>=0,(C8+E8)-(D8+F8),0) -> 0 | H8: =IF((C8+E8)-(D8+F8)<0,-((C8+E8)-(D8+F8)),0) -> 0
A9: =COA!$A$8 -> 1450 | B9: =COA!$B$8 -> مجمع إهلاك المعدات | C9: =SUMIF('Opening Balances'!$A$5:$A$6,A9,'Opening Balances'!$C$5:$C$6) -> 0 | D9: =SUMIF('Opening Balances'!$A$5:$A$6,A9,'Opening Balances'!$D$5:$D$6) -> 0 | E9: =SUMIF(Journal!$D$5:$D$64,A9,Journal!$H$5:$H$64) -> 0 | F9: =SUMIF(Journal!$D$5:$D$64,A9,Journal!$I$5:$I$64) -> 0 | G9: =IF((C9+E9)-(D9+F9)>=0,(C9+E9)-(D9+F9),0) -> 0 | H9: =IF((C9+E9)-(D9+F9)<0,-((C9+E9)-(D9+F9)),0) -> 0
A10: =COA!$A$9 -> 1500 | B10: =COA!$B$9 -> مصروفات مدفوعة مقدماً | C10: =SUMIF('Opening Balances'!$A$5:$A$6,A10,'Opening Balances'!$C$5:$C$6) -> 0 | D10: =SUMIF('Opening Balances'!$A$5:$A$6,A10,'Opening Balances'!$D$5:$D$6) -> 0 | E10: =SUMIF(Journal!$D$5:$D$64,A10,Journal!$H$5:$H$64) -> 0 | F10: =SUMIF(Journal!$D$5:$D$64,A10,Journal!$I$5:$I$64) -> 0 | G10: =IF((C10+E10)-(D10+F10)>=0,(C10+E10)-(D10+F10),0) -> 0 | H10: =IF((C10+E10)-(D10+F10)<0,-((C10+E10)-(D10+F10)),0) -> 0
A11: =COA!$A$10 -> 1600 | B11: =COA!$B$10 -> ضريبة القيمة المضافة - مدخلات | C11: =SUMIF('Opening Balances'!$A$5:$A$6,A11,'Opening Balances'!$C$5:$C$6) -> 0 | D11: =SUMIF('Opening Balances'!$A$5:$A$6,A11,'Opening Balances'!$D$5:$D$6) -> 0 | E11: =SUMIF(Journal!$D$5:$D$64,A11,Journal!$H$5:$H$64) -> 0 | F11: =SUMIF(Journal!$D$5:$D$64,A11,Journal!$I$5:$I$64) -> 0 | G11: =IF((C11+E11)-(D11+F11)>=0,(C11+E11)-(D11+F11),0) -> 0 | H11: =IF((C11+E11)-(D11+F11)<0,-((C11+E11)-(D11+F11)),0) -> 0
A12: =COA!$A$11 -> 2100 | B12: =COA!$B$11 -> الموردون (الدائنون) | C12: =SUMIF('Opening Balances'!$A$5:$A$6,A12,'Opening Balances'!$C$5:$C$6) -> 0 | D12: =SUMIF('Opening Balances'!$A$5:$A$6,A12,'Opening Balances'!$D$5:$D$6) -> 0 | E12: =SUMIF(Journal!$D$5:$D$64,A12,Journal!$H$5:$H$64) -> 0 | F12: =SUMIF(Journal!$D$5:$D$64,A12,Journal!$I$5:$I$64) -> 0 | G12: =IF((C12+E12)-(D12+F12)>=0,(C12+E12)-(D12+F12),0) -> 0 | H12: =IF((C12+E12)-(D12+F12)<0,-((C12+E12)-(D12+F12)),0) -> 0
A13: =COA!$A$12 -> 2200 | B13: =COA!$B$12 -> مصروفات مستحقة | C13: =SUMIF('Opening Balances'!$A$5:$A$6,A13,'Opening Balances'!$C$5:$C$6) -> 0 | D13: =SUMIF('Opening Balances'!$A$5:$A$6,A13,'Opening Balances'!$D$5:$D$6) -> 0 | E13: =SUMIF(Journal!$D$5:$D$64,A13,Journal!$H$5:$H$64) -> 0 | F13: =SUMIF(Journal!$D$5:$D$64,A13,Journal!$I$5:$I$64) -> 0 | G13: =IF((C13+E13)-(D13+F13)>=0,(C13+E13)-(D13+F13),0) -> 0 | H13: =IF((C13+E13)-(D13+F13)<0,-((C13+E13)-(D13+F13)),0) -> 0
A14: =COA!$A$13 -> 2300 | B14: =COA!$B$13 -> ضريبة القيمة المضافة - مخرجات | C14: =SUMIF('Opening Balances'!$A$5:$A$6,A14,'Opening Balances'!$C$5:$C$6) -> 0 | D14: =SUMIF('Opening Balances'!$A$5:$A$6,A14,'Opening Balances'!$D$5:$D$6) -> 0 | E14: =SUMIF(Journal!$D$5:$D$64,A14,Journal!$H$5:$H$64) -> 0 | F14: =SUMIF(Journal!$D$5:$D$64,A14,Journal!$I$5:$I$64) -> 0 | G14: =IF((C14+E14)-(D14+F14)>=0,(C14+E14)-(D14+F14),0) -> 0 | H14: =IF((C14+E14)-(D14+F14)<0,-((C14+E14)-(D14+F14)),0) -> 0
A15: =COA!$A$14 -> 2400 | B15: =COA!$B$14 -> ضريبة الدخل مستحقة | C15: =SUMIF('Opening Balances'!$A$5:$A$6,A15,'Opening Balances'!$C$5:$C$6) -> 0 | D15: =SUMIF('Opening Balances'!$A$5:$A$6,A15,'Opening Balances'!$D$5:$D$6) -> 0 | E15: =SUMIF(Journal!$D$5:$D$64,A15,Journal!$H$5:$H$64) -> 0 | F15: =SUMIF(Journal!$D$5:$D$64,A15,Journal!$I$5:$I$64) -> 0 | G15: =IF((C15+E15)-(D15+F15)>=0,(C15+E15)-(D15+F15),0) -> 0 | H15: =IF((C15+E15)-(D15+F15)<0,-((C15+E15)-(D15+F15)),0) -> 0
A16: =COA!$A$15 -> 2500 | B16: =COA!$B$15 -> قرض قصير الأجل | C16: =SUMIF('Opening Balances'!$A$5:$A$6,A16,'Opening Balances'!$C$5:$C$6) -> 0 | D16: =SUMIF('Opening Balances'!$A$5:$A$6,A16,'Opening Balances'!$D$5:$D$6) -> 0 | E16: =SUMIF(Journal!$D$5:$D$64,A16,Journal!$H$5:$H$64) -> 0 | F16: =SUMIF(Journal!$D$5:$D$64,A16,Journal!$I$5:$I$64) -> 0 | G16: =IF((C16+E16)-(D16+F16)>=0,(C16+E16)-(D16+F16),0) -> 0 | H16: =IF((C16+E16)-(D16+F16)<0,-((C16+E16)-(D16+F16)),0) -> 0
A17: =COA!$A$16 -> 3100 | B17: =COA!$B$16 -> رأس المال | C17: =SUMIF('Opening Balances'!$A$5:$A$6,A17,'Opening Balances'!$C$5:$C$6) -> 0 | D17: =SUMIF('Opening Balances'!$A$5:$A$6,A17,'Opening Balances'!$D$5:$D$6) -> 20000000 | E17: =SUMIF(Journal!$D$5:$D$64,A17,Journal!$H$5:$H$64) -> 0 | F17: =SUMIF(Journal!$D$5:$D$64,A17,Journal!$I$5:$I$64) -> 0 | G17: =IF((C17+E17)-(D17+F17)>=0,(C17+E17)-(D17+F17),0) -> 0 | H17: =IF((C17+E17)-(D17+F17)<0,-((C17+E17)-(D17+F17)),0) -> 20000000
A18: =COA!$A$17 -> 3200 | B18: =COA!$B$17 -> الأرباح المحتجزة | C18: =SUMIF('Opening Balances'!$A$5:$A$6,A18,'Opening Balances'!$C$5:$C$6) -> 0 | D18: =SUMIF('Opening Balances'!$A$5:$A$6,A18,'Opening Balances'!$D$5:$D$6) -> 0 | E18: =SUMIF(Journal!$D$5:$D$64,A18,Journal!$H$5:$H$64) -> 0 | F18: =SUMIF(Journal!$D$5:$D$64,A18,Journal!$I$5:$I$64) -> 0 | G18: =IF((C18+E18)-(D18+F18)>=0,(C18+E18)-(D18+F18),0) -> 0 | H18: =IF((C18+E18)-(D18+F18)<0,-((C18+E18)-(D18+F18)),0) -> 0
A19: =COA!$A$18 -> 3300 | B19: =COA!$B$18 -> مسحوبات / توزيعات أرباح | C19: =SUMIF('Opening Balances'!$A$5:$A$6,A19,'Opening Balances'!$C$5:$C$6) -> 0 | D19: =SUMIF('Opening Balances'!$A$5:$A$6,A19,'Opening Balances'!$D$5:$D$6) -> 0 | E19: =SUMIF(Journal!$D$5:$D$64,A19,Journal!$H$5:$H$64) -> 0 | F19: =SUMIF(Journal!$D$5:$D$64,A19,Journal!$I$5:$I$64) -> 0 | G19: =IF((C19+E19)-(D19+F19)>=0,(C19+E19)-(D19+F19),0) -> 0 | H19: =IF((C19+E19)-(D19+F19)<0,-((C19+E19)-(D19+F19)),0) -> 0
A20: =COA!$A$19 -> 4100 | B20: =COA!$B$19 -> إيرادات المبيعات | C20: =SUMIF('Opening Balances'!$A$5:$A$6,A20,'Opening Balances'!$C$5:$C$6) -> 0 | D20: =SUMIF('Opening Balances'!$A$5:$A$6,A20,'Opening Balances'!$D$5:$D$6) -> 0 | E20: =SUMIF(Journal!$D$5:$D$64,A20,Journal!$H$5:$H$64) -> 0 | F20: =SUMIF(Journal!$D$5:$D$64,A20,Journal!$I$5:$I$64) -> 0 | G20: =IF((C20+E20)-(D20+F20)>=0,(C20+E20)-(D20+F20),0) -> 0 | H20: =IF((C20+E20)-(D20+F20)<0,-((C20+E20)-(D20+F20)),0) -> 0
A21: =COA!$A$20 -> 4200 | B21: =COA!$B$20 -> إيرادات أخرى | C21: =SUMIF('Opening Balances'!$A$5:$A$6,A21,'Opening Balances'!$C$5:$C$6) -> 0 | D21: =SUMIF('Opening Balances'!$A$5:$A$6,A21,'Opening Balances'!$D$5:$D$6) -> 0 | E21: =SUMIF(Journal!$D$5:$D$64,A21,Journal!$H$5:$H$64) -> 0 | F21: =SUMIF(Journal!$D$5:$D$64,A21,Journal!$I$5:$I$64) -> 0 | G21: =IF((C21+E21)-(D21+F21)>=0,(C21+E21)-(D21+F21),0) -> 0 | H21: =IF((C21+E21)-(D21+F21)<0,-((C21+E21)-(D21+F21)),0) -> 0
A22: =COA!$A$21 -> 5100 | B22: =COA!$B$21 -> تكلفة البضاعة المباعة | C22: =SUMIF('Opening Balances'!$A$5:$A$6,A22,'Opening Balances'!$C$5:$C$6) -> 0 | D22: =SUMIF('Opening Balances'!$A$5:$A$6,A22,'Opening Balances'!$D$5:$D$6) -> 0 | E22: =SUMIF(Journal!$D$5:$D$64,A22,Journal!$H$5:$H$64) -> 0 | F22: =SUMIF(Journal!$D$5:$D$64,A22,Journal!$I$5:$I$64) -> 0 | G22: =IF((C22+E22)-(D22+F22)>=0,(C22+E22)-(D22+F22),0) -> 0 | H22: =IF((C22+E22)-(D22+F22)<0,-((C22+E22)-(D22+F22)),0) -> 0
A23: =COA!$A$22 -> 5200 | B23: =COA!$B$22 -> رواتب وأجور | C23: =SUMIF('Opening Balances'!$A$5:$A$6,A23,'Opening Balances'!$C$5:$C$6) -> 0 | D23: =SUMIF('Opening Balances'!$A$5:$A$6,A23,'Opening Balances'!$D$5:$D$6) -> 0 | E23: =SUMIF(Journal!$D$5:$D$64,A23,Journal!$H$5:$H$64) -> 0 | F23: =SUMIF(Journal!$D$5:$D$64,A23,Journal!$I$5:$I$64) -> 0 | G23: =IF((C23+E23)-(D23+F23)>=0,(C23+E23)-(D23+F23),0) -> 0 | H23: =IF((C23+E23)-(D23+F23)<0,-((C23+E23)-(D23+F23)),0) -> 0
A24: =COA!$A$23 -> 5300 | B24: =COA!$B$23 -> إيجار | C24: =SUMIF('Opening Balances'!$A$5:$A$6,A24,'Opening Balances'!$C$5:$C$6) -> 0 | D24: =SUMIF('Opening Balances'!$A$5:$A$6,A24,'Opening Balances'!$D$5:$D$6) -> 0 | E24: =SUMIF(Journal!$D$5:$D$64,A24,Journal!$H$5:$H$64) -> 0 | F24: =SUMIF(Journal!$D$5:$D$64,A24,Journal!$I$5:$I$64) -> 0 | G24: =IF((C24+E24)-(D24+F24)>=0,(C24+E24)-(D24+F24),0) -> 0 | H24: =IF((C24+E24)-(D24+F24)<0,-((C24+E24)-(D24+F24)),0) -> 0
A25: =COA!$A$24 -> 5400 | B25: =COA!$B$24 -> خدمات (كهرباء واتصالات) | C25: =SUMIF('Opening Balances'!$A$5:$A$6,A25,'Opening Balances'!$C$5:$C$6) -> 0 | D25: =SUMIF('Opening Balances'!$A$5:$A$6,A25,'Opening Balances'!$D$5:$D$6) -> 0 | E25: =SUMIF(Journal!$D$5:$D$64,A25,Journal!$H$5:$H$64) -> 0 | F25: =SUMIF(Journal!$D$5:$D$64,A25,Journal!$I$5:$I$64) -> 0 | G25: =IF((C25+E25)-(D25+F25)>=0,(C25+E25)-(D25+F25),0) -> 0 | H25: =IF((C25+E25)-(D25+F25)<0,-((C25+E25)-(D25+F25)),0) -> 0
A26: =COA!$A$25 -> 5500 | B26: =COA!$B$25 -> مصروفات تسويق | C26: =SUMIF('Opening Balances'!$A$5:$A$6,A26,'Opening Balances'!$C$5:$C$6) -> 0 | D26: =SUMIF('Opening Balances'!$A$5:$A$6,A26,'Opening Balances'!$D$5:$D$6) -> 0 | E26: =SUMIF(Journal!$D$5:$D$64,A26,Journal!$H$5:$H$64) -> 0 | F26: =SUMIF(Journal!$D$5:$D$64,A26,Journal!$I$5:$I$64) -> 0 | G26: =IF((C26+E26)-(D26+F26)>=0,(C26+E26)-(D26+F26),0) -> 0 | H26: =IF((C26+E26)-(D26+F26)<0,-((C26+E26)-(D26+F26)),0) -> 0
A27: =COA!$A$26 -> 5600 | B27: =COA!$B$26 -> مصروفات إدارية عامة | C27: =SUMIF('Opening Balances'!$A$5:$A$6,A27,'Opening Balances'!$C$5:$C$6) -> 0 | D27: =SUMIF('Opening Balances'!$A$5:$A$6,A27,'Opening Balances'!$D$5:$D$6) -> 0 | E27: =SUMIF(Journal!$D$5:$D$64,A27,Journal!$H$5:$H$64) -> 0 | F27: =SUMIF(Journal!$D$5:$D$64,A27,Journal!$I$5:$I$64) -> 0 | G27: =IF((C27+E27)-(D27+F27)>=0,(C27+E27)-(D27+F27),0) -> 0 | H27: =IF((C27+E27)-(D27+F27)<0,-((C27+E27)-(D27+F27)),0) -> 0
A28: =COA!$A$27 -> 5700 | B28: =COA!$B$27 -> إهلاك | C28: =SUMIF('Opening Balances'!$A$5:$A$6,A28,'Opening Balances'!$C$5:$C$6) -> 0 | D28: =SUMIF('Opening Balances'!$A$5:$A$6,A28,'Opening Balances'!$D$5:$D$6) -> 0 | E28: =SUMIF(Journal!$D$5:$D$64,A28,Journal!$H$5:$H$64) -> 0 | F28: =SUMIF(Journal!$D$5:$D$64,A28,Journal!$I$5:$I$64) -> 0 | G28: =IF((C28+E28)-(D28+F28)>=0,(C28+E28)-(D28+F28),0) -> 0 | H28: =IF((C28+E28)-(D28+F28)<0,-((C28+E28)-(D28+F28)),0) -> 0
A29: =COA!$A$28 -> 5800 | B29: =COA!$B$28 -> مصروفات تمويل (فوائد بنكية) | C29: =SUMIF('Opening Balances'!$A$5:$A$6,A29,'Opening Balances'!$C$5:$C$6) -> 0 | D29: =SUMIF('Opening Balances'!$A$5:$A$6,A29,'Opening Balances'!$D$5:$D$6) -> 0 | E29: =SUMIF(Journal!$D$5:$D$64,A29,Journal!$H$5:$H$64) -> 0 | F29: =SUMIF(Journal!$D$5:$D$64,A29,Journal!$I$5:$I$64) -> 0 | G29: =IF((C29+E29)-(D29+F29)>=0,(C29+E29)-(D29+F29),0) -> 0 | H29: =IF((C29+E29)-(D29+F29)<0,-((C29+E29)-(D29+F29)),0) -> 0
A30: الإجمالي | C30: =SUM(C5:C29) -> 20000000 | D30: =SUM(D5:D29) -> 20000000 | E30: =SUM(E5:E29) -> 0 | F30: =SUM(F5:F29) -> 0 | G30: =SUM(G5:G29) -> 20000000 | H30: =SUM(H5:H29) -> 20000000
A31: حالة التوازن (افتتاحي/حركة/ختامي) | C31: =IF(AND(ROUND(C30-D30,2)=0,ROUND(E30-F30,2)=0,ROUND(G30-H30,2)=0),"متوازن","غير متوازن") -> متوازن
A33: دليل الألوان: أزرق = خلية إدخال يعدّلها المستخدم | أسود = صيغة محسوبة تلقائياً | أصفر = افتراض/معلمة تدريبية رئيسية | رمادي = عمود مساعد للحسابات (لا يُعدّل)

Sheet Customers
A1: العملاء - Customers
A3: الرمز | B3: اسم العميل | C3: رقم الهاتف | D3: أجل السداد الافتراضي (يوم) | E3: ملاحظات
A4: C001 | B4: عميل تدريبي رقم 1 | C4: 05xxxxxxxx | D4: 30
A5: C002 | B5: عميل تدريبي رقم 2 | C5: 05xxxxxxxx | D5: 30
A6: C003 | B6: عميل تدريبي رقم 3 | C6: 05xxxxxxxx | D6: 30
A7: C004 | B7: عميل تدريبي رقم 4 | C7: 05xxxxxxxx | D7: 30
A8: C005 | B8: عميل تدريبي رقم 5 | C8: 05xxxxxxxx | D8: 30
A9: C006 | B9: عميل تدريبي رقم 6 | C9: 05xxxxxxxx | D9: 30
A10: C007 | B10: عميل تدريبي رقم 7 | C10: 05xxxxxxxx | D10: 30
A11: C008 | B11: عميل تدريبي رقم 8 | C11: 05xxxxxxxx | D11: 30
A12: C009 | B12: عميل تدريبي رقم 9 | C12: 05xxxxxxxx | D12: 30
A13: C010 | B13: عميل تدريبي رقم 10 | C13: 05xxxxxxxx | D13: 30
A15: دليل الألوان: أزرق = خلية إدخال يعدّلها المستخدم | أسود = صيغة محسوبة تلقائياً | أصفر = افتراض/معلمة تدريبية رئيسية | رمادي = عمود مساعد للحسابات (لا يُعدّل)

Sheet Suppliers
A1: الموردون - Suppliers
A3: الرمز | B3: اسم المورد | C3: التخصص | D3: أجل السداد الافتراضي (يوم) | E3: ملاحظات
A4: S001 | B4: مورد المعدات | C4: معدات | D4: 30
A5: S002 | B5: مورد الأجهزة | C5: أجهزة | D5: 30
A6: S003 | B6: مورد خدمات الربط والاتصالات | C6: ربط واتصالات | D6: 30
A7: S004 | B7: المؤجّر - عقد الإيجار | C7: إيجار | D7: 30
A8: S005 | B8: مورد الخدمات العامة | C8: خدمات | D8: 30
A10: دليل الألوان: أزرق = خلية إدخال يعدّلها المستخدم | أسود = صيغة محسوبة تلقائياً | أصفر = افتراض/معلمة تدريبية رئيسية | رمادي = عمود مساعد للحسابات (لا يُعدّل)

Sheet AR AP
A1: أعمار الذمم - العملاء والموردون (AR / AP)
A3: ذمم العملاء (مدينون)
A4: الرمز | B4: اسم العميل | C4: مدين | D4: دائن | E4: الرصيد
A5: =Customers!A4 -> C001 | B5: =Customers!B4 -> عميل تدريبي رقم 1 | C5: =SUMIFS(Journal!$H$5:$H$64,Journal!$F$5:$F$64,A5) -> 0 | D5: =SUMIFS(Journal!$I$5:$I$64,Journal!$F$5:$F$64,A5) -> 0 | E5: =C5-D5 -> 0
A6: =Customers!A5 -> C002 | B6: =Customers!B5 -> عميل تدريبي رقم 2 | C6: =SUMIFS(Journal!$H$5:$H$64,Journal!$F$5:$F$64,A6) -> 0 | D6: =SUMIFS(Journal!$I$5:$I$64,Journal!$F$5:$F$64,A6) -> 0 | E6: =C6-D6 -> 0
A7: =Customers!A6 -> C003 | B7: =Customers!B6 -> عميل تدريبي رقم 3 | C7: =SUMIFS(Journal!$H$5:$H$64,Journal!$F$5:$F$64,A7) -> 0 | D7: =SUMIFS(Journal!$I$5:$I$64,Journal!$F$5:$F$64,A7) -> 0 | E7: =C7-D7 -> 0
A8: =Customers!A7 -> C004 | B8: =Customers!B7 -> عميل تدريبي رقم 4 | C8: =SUMIFS(Journal!$H$5:$H$64,Journal!$F$5:$F$64,A8) -> 0 | D8: =SUMIFS(Journal!$I$5:$I$64,Journal!$F$5:$F$64,A8) -> 0 | E8: =C8-D8 -> 0
A9: =Customers!A8 -> C005 | B9: =Customers!B8 -> عميل تدريبي رقم 5 | C9: =SUMIFS(Journal!$H$5:$H$64,Journal!$F$5:$F$64,A9) -> 0 | D9: =SUMIFS(Journal!$I$5:$I$64,Journal!$F$5:$F$64,A9) -> 0 | E9: =C9-D9 -> 0
A10: =Customers!A9 -> C006 | B10: =Customers!B9 -> عميل تدريبي رقم 6 | C10: =SUMIFS(Journal!$H$5:$H$64,Journal!$F$5:$F$64,A10) -> 0 | D10: =SUMIFS(Journal!$I$5:$I$64,Journal!$F$5:$F$64,A10) -> 0 | E10: =C10-D10 -> 0
A11: =Customers!A10 -> C007 | B11: =Customers!B10 -> عميل تدريبي رقم 7 | C11: =SUMIFS(Journal!$H$5:$H$64,Journal!$F$5:$F$64,A11) -> 0 | D11: =SUMIFS(Journal!$I$5:$I$64,Journal!$F$5:$F$64,A11) -> 0 | E11: =C11-D11 -> 0
A12: =Customers!A11 -> C008 | B12: =Customers!B11 -> عميل تدريبي رقم 8 | C12: =SUMIFS(Journal!$H$5:$H$64,Journal!$F$5:$F$64,A12) -> 0 | D12: =SUMIFS(Journal!$I$5:$I$64,Journal!$F$5:$F$64,A12) -> 0 | E12: =C12-D12 -> 0
A13: =Customers!A12 -> C009 | B13: =Customers!B12 -> عميل تدريبي رقم 9 | C13: =SUMIFS(Journal!$H$5:$H$64,Journal!$F$5:$F$64,A13) -> 0 | D13: =SUMIFS(Journal!$I$5:$I$64,Journal!$F$5:$F$64,A13) -> 0 | E13: =C13-D13 -> 0
A14: =Customers!A13 -> C010 | B14: =Customers!B13 -> عميل تدريبي رقم 10 | C14: =SUMIFS(Journal!$H$5:$H$64,Journal!$F$5:$F$64,A14) -> 0 | D14: =SUMIFS(Journal!$I$5:$I$64,Journal!$F$5:$F$64,A14) -> 0 | E14: =C14-D14 -> 0
A15: الإجمالي | C15: =SUM(C5:C14) -> 0 | D15: =SUM(D5:D14) -> 0 | E15: =SUM(E5:E14) -> 0
A17: ذمم الموردين (دائنون)
A18: الرمز | B18: اسم العميل | C18: مدين | D18: دائن | E18: الرصيد
A19: =Suppliers!A4 -> S001 | B19: =Suppliers!B4 -> مورد المعدات | C19: =SUMIFS(Journal!$H$5:$H$64,Journal!$F$5:$F$64,A19) -> 0 | D19: =SUMIFS(Journal!$I$5:$I$64,Journal!$F$5:$F$64,A19) -> 0 | E19: =D19-C19 -> 0
A20: =Suppliers!A5 -> S002 | B20: =Suppliers!B5 -> مورد الأجهزة | C20: =SUMIFS(Journal!$H$5:$H$64,Journal!$F$5:$F$64,A20) -> 0 | D20: =SUMIFS(Journal!$I$5:$I$64,Journal!$F$5:$F$64,A20) -> 0 | E20: =D20-C20 -> 0
A21: =Suppliers!A6 -> S003 | B21: =Suppliers!B6 -> مورد خدمات الربط والاتصالات | C21: =SUMIFS(Journal!$H$5:$H$64,Journal!$F$5:$F$64,A21) -> 0 | D21: =SUMIFS(Journal!$I$5:$I$64,Journal!$F$5:$F$64,A21) -> 0 | E21: =D21-C21 -> 0
A22: =Suppliers!A7 -> S004 | B22: =Suppliers!B7 -> المؤجّر - عقد الإيجار | C22: =SUMIFS(Journal!$H$5:$H$64,Journal!$F$5:$F$64,A22) -> 0 | D22: =SUMIFS(Journal!$I$5:$I$64,Journal!$F$5:$F$64,A22) -> 0 | E22: =D22-C22 -> 0
A23: =Suppliers!A8 -> S005 | B23: =Suppliers!B8 -> مورد الخدمات العامة | C23: =SUMIFS(Journal!$H$5:$H$64,Journal!$F$5:$F$64,A23) -> 0 | D23: =SUMIFS(Journal!$I$5:$I$64,Journal!$F$5:$F$64,A23) -> 0 | E23: =D23-C23 -> 0
A24: الإجمالي | C24: =SUM(C19:C23) -> 0 | D24: =SUM(D19:D23) -> 0 | E24: =SUM(E19:E23) -> 0
A26: دليل الألوان: أزرق = خلية إدخال يعدّلها المستخدم | أسود = صيغة محسوبة تلقائياً | أصفر = افتراض/معلمة تدريبية رئيسية | رمادي = عمود مساعد للحسابات (لا يُعدّل)

Sheet Bank
A1: البنك - Bank Reconciliation
A2: حساب 1100 - كما في 2026-01-31
A4: رصيد الدفاتر (حساب 1100) | B4: ='Trial Balance'!G5-'Trial Balance'!H5 -> 20000000
A5: رصيد كشف الحساب البنكي | B5: 20000000
A6: زائد: إيداعات بالطريق (لم تظهر بالكشف) | B6: 0
A7: ناقص: مدفوعات معلقة (لم تظهر بالكشف) | B7: 0
A8: رصيد الدفاتر المعدّل | B8: =B4+B6-B7 -> 20000000
A9: فرق المطابقة (يجب أن يكون صفراً) | B9: =B8-B5 -> 0
A11: دليل الألوان: أزرق = خلية إدخال يعدّلها المستخدم | أسود = صيغة محسوبة تلقائياً | أصفر = افتراض/معلمة تدريبية رئيسية | رمادي = عمود مساعد للحسابات (لا يُعدّل)

Sheet VAT
A1: ضريبة القيمة المضافة - VAT
A3: المعدل التدريبي لضريبة القيمة المضافة | B3: 0.15
A4: ضريبة المدخلات (حساب 1600) | B4: ='Trial Balance'!G11-'Trial Balance'!H11 -> 0
A5: ضريبة المخرجات (حساب 2300) | B5: ='Trial Balance'!H14-'Trial Balance'!G14 -> 0
A6: صافي الفرق (مخرجات - مدخلات = مستحق للسداد) | B6: =B5-B4 -> 0
A8: دليل الألوان: أزرق = خلية إدخال يعدّلها المستخدم | أسود = صيغة محسوبة تلقائياً | أصفر = افتراض/معلمة تدريبية رئيسية | رمادي = عمود مساعد للحسابات (لا يُعدّل)

Sheet Fixed Assets
A1: الأصول الثابتة - Fixed Assets
A2: لا توجد أصول مضافة عند بداية المحاكاة
A4: كود الأصل | B4: اسم الأصل | C4: تاريخ الشراء | D4: التكلفة | E4: العمر الإنتاجي (سنوات) | F4: طريقة الإهلاك | G4: الإهلاك الشهري | H4: مجمع الإهلاك | I4: صافي القيمة الدفترية
G5: =IF(OR(D5="",E5="",E5=0),"",D5/(E5*12)) | I5: =IF(D5="","",D5-IF(H5="",0,H5))
G6: =IF(OR(D6="",E6="",E6=0),"",D6/(E6*12)) | I6: =IF(D6="","",D6-IF(H6="",0,H6))
G7: =IF(OR(D7="",E7="",E7=0),"",D7/(E7*12)) | I7: =IF(D7="","",D7-IF(H7="",0,H7))
G8: =IF(OR(D8="",E8="",E8=0),"",D8/(E8*12)) | I8: =IF(D8="","",D8-IF(H8="",0,H8))
G9: =IF(OR(D9="",E9="",E9=0),"",D9/(E9*12)) | I9: =IF(D9="","",D9-IF(H9="",0,H9))
G10: =IF(OR(D10="",E10="",E10=0),"",D10/(E10*12)) | I10: =IF(D10="","",D10-IF(H10="",0,H10))
G11: =IF(OR(D11="",E11="",E11=0),"",D11/(E11*12)) | I11: =IF(D11="","",D11-IF(H11="",0,H11))
G12: =IF(OR(D12="",E12="",E12=0),"",D12/(E12*12)) | I12: =IF(D12="","",D12-IF(H12="",0,H12))
G13: =IF(OR(D13="",E13="",E13=0),"",D13/(E13*12)) | I13: =IF(D13="","",D13-IF(H13="",0,H13))
G14: =IF(OR(D14="",E14="",E14=0),"",D14/(E14*12)) | I14: =IF(D14="","",D14-IF(H14="",0,H14))
G15: =IF(OR(D15="",E15="",E15=0),"",D15/(E15*12)) | I15: =IF(D15="","",D15-IF(H15="",0,H15))
G16: =IF(OR(D16="",E16="",E16=0),"",D16/(E16*12)) | I16: =IF(D16="","",D16-IF(H16="",0,H16))
... G19: =IF(OR(D19="",E19="",E19=0),"",D19/(E19*12)) | I19: =IF(D19="","",D19-IF(H19="",0,H19))
A21: دليل الألوان: أزرق = خلية إدخال يعدّلها المستخدم | أسود = صيغة محسوبة تلقائياً | أصفر = افتراض/معلمة تدريبية رئيسية | رمادي = عمود مساعد للحسابات (لا يُعدّل)

Sheet Adjustments
A1: التسويات - Adjustments
A3: رقم التسوية | B3: التاريخ | C3: الوصف | D3: المستند المرجعي | E3: الحالة | F3: رقم القيد المرتبط | G3: ملاحظات
A4: 1
A5: 2
A6: 3
A7: 4
A8: 5
A9: 6
A10: 7
A11: 8
A12: 9
A13: 10
A14: 11
A15: 12
... A18: 15
A20: دليل الألوان: أزرق = خلية إدخال يعدّلها المستخدم | أسود = صيغة محسوبة تلقائياً | أصفر = افتراض/معلمة تدريبية رئيسية | رمادي = عمود مساعد للحسابات (لا يُعدّل)

Sheet Income Statement
A1: قائمة الدخل - Income Statement
A2: للفترة من 2026-01-01 إلى 2026-01-31
A4: إجمالي الإيرادات | B4: =SUMIFS(Journal!$I$5:$I$64,Journal!$D$5:$D$64,">=4100",Journal!$D$5:$D$64,"<5000")-SUMIFS(Journal!$H$5:$H$64,Journal!$D$5:$D$64,">=4100",Journal!$D$5:$D$64,"<5000") -> 0
A5: إجمالي المصروفات | B5: =SUMIFS(Journal!$H$5:$H$64,Journal!$D$5:$D$64,">=5100",Journal!$D$5:$D$64,"<6000")-SUMIFS(Journal!$I$5:$I$64,Journal!$D$5:$D$64,">=5100",Journal!$D$5:$D$64,"<6000") -> 0
A6: صافي الربح قبل الضريبة | B6: =B4-B5 -> 0
A7: ضريبة الدخل (بمعدل ورقة Company Profile) | B7: =IF(B6>0,B6*'Company Profile'!B9,0) -> 0
A8: صافي الربح بعد الضريبة | B8: =B6-B7 -> 0
A10: ملاحظة: تُعرض الضريبة هنا كتقدير فقط. تصبح مستحقة فعلياً على قائمة المركز المالي بعد تسجيل قيد تسوية بضريبة الدخل (Dr مصروف الضريبة / Cr 2400) في ورقة Journal.
A12: دليل الألوان: أزرق = خلية إدخال يعدّلها المستخدم | أسود = صيغة محسوبة تلقائياً | أصفر = افتراض/معلمة تدريبية رئيسية | رمادي = عمود مساعد للحسابات (لا يُعدّل)

Sheet Balance Sheet
A1: قائمة المركز المالي - Balance Sheet
A2: كما في 2026-01-31
A4: إجمالي الأصول | B4: =SUMIFS('Trial Balance'!$G$5:$G$29,'Trial Balance'!$A$5:$A$29,">=1000",'Trial Balance'!$A$5:$A$29,"<2000")-SUMIFS('Trial Balance'!$H$5:$H$29,'Trial Balance'!$A$5:$A$29,">=1000",'Trial Balance'!$A$5:$A$29,"<2000") -> 20000000
A5: إجمالي الالتزامات | B5: =SUMIFS('Trial Balance'!$H$5:$H$29,'Trial Balance'!$A$5:$A$29,">=2000",'Trial Balance'!$A$5:$A$29,"<3000")-SUMIFS('Trial Balance'!$G$5:$G$29,'Trial Balance'!$A$5:$A$29,">=2000",'Trial Balance'!$A$5:$A$29,"<3000") -> 0
A6: حقوق الملكية (رأس المال والأرباح المحتجزة) | B6: =SUMIFS('Trial Balance'!$H$5:$H$29,'Trial Balance'!$A$5:$A$29,">=3000",'Trial Balance'!$A$5:$A$29,"<4000")-SUMIFS('Trial Balance'!$G$5:$G$29,'Trial Balance'!$A$5:$A$29,">=3000",'Trial Balance'!$A$5:$A$29,"<4000") -> 20000000
A7: زائد: صافي ربح الفترة الحالية (قبل تسوية الضريبة) | B7: ='Income Statement'!B6 -> 0
A8: إجمالي حقوق الملكية | B8: =B6+B7 -> 20000000
A9: إجمالي الالتزامات وحقوق الملكية | B9: =B5+B8 -> 20000000
A10: حالة التوازن (الأصول = الالتزامات + حقوق الملكية) | B10: =IF(ROUND(B4-B9,2)=0,"متوازن","غير متوازن") -> متوازن
A12: دليل الألوان: أزرق = خلية إدخال يعدّلها المستخدم | أسود = صيغة محسوبة تلقائياً | أصفر = افتراض/معلمة تدريبية رئيسية | رمادي = عمود مساعد للحسابات (لا يُعدّل)

Sheet Training Progress
A1: تقدم التدريب - Training Progress
A3: م | B3: الموضوع التدريبي | C3: الحالة | D3: تاريخ البدء | E3: تاريخ الانتهاء | F3: ملاحظات
A4: 1 | B4: 1. أساسيات المدين والدائن وقاعدة القيد المزدوج | C4: لم يبدأ
A5: 2 | B5: 2. تسجيل القيود في دفتر اليومية (Journal) | C5: لم يبدأ
A6: 3 | B6: 3. الترحيل إلى دفتر الأستاذ وإعداد ميزان المراجعة | C6: لم يبدأ
A7: 4 | B7: 4. العملاء والموردون وأعمار الذمم (AR/AP) | C7: لم يبدأ
A8: 5 | B8: 5. مطابقة البنك، ضريبة القيمة المضافة، والأصول الثابتة | C8: لم يبدأ
A9: 6 | B9: 6. التسويات الجردية وإقفال الحسابات وإعداد القوائم المالية | C9: لم يبدأ
A11: دليل الألوان: أزرق = خلية إدخال يعدّلها المستخدم | أسود = صيغة محسوبة تلقائياً | أصفر = افتراض/معلمة تدريبية رئيسية | رمادي = عمود مساعد للحسابات (لا يُعدّل)

Sheet Company Log
A1: سجل الشركة - Company Log
A3: التاريخ | B3: الإصدار | C3: الإجراء | D3: الوصف | E3: الخطوة التالية
A4: 2026-01-01 | B4: 1.0 | C4: تأسيس الملف | D4: إنشاء نموذج المحاكاة المحاسبية التدريبي بكامل أوراقه (دليل الحسابات، اليومية، الأستاذ، القوائم المالية، والعملاء والموردون). | E4: بدء الحالة التدريبية الأولى ومناقشة المستندات المؤيدة للقيود.
A25: دليل الألوان: أزرق = خلية إدخال يعدّلها المستخدم | أسود = صيغة محسوبة تلقائياً | أصفر = افتراض/معلمة تدريبية رئيسية | رمادي = عمود مساعد للحسابات (لا يُعدّل)
